Workbook

Sheet DASHBOARD
A1: 📊 ENGLISH CLASS MANAGEMENT — DASHBOARD
A2: All metrics auto-calculate from STUDENTS, ENROLLMENTS & ATTENDANCE_LOG. Yellow cells = inputs you can change.
A4: ▎ SECTION 1 — OVERVIEW
A5: ACTIVE STUDENTS | C5: OVERALL ATTENDANCE RATE | E5: TOTAL STUDENTS | G5: ✅ Completed | K5: =IFERROR(COUNTIF(ATTENDANCE_LOG!$G:$G,"Present")/(COUNTIF(ATTENDANCE_LOG!$G:$G,"Present")+COUNTIF(ATTENDANCE_LOG!$G:$G,"Absent")),0) -> 0.86387518
A6: =COUNTIF(STUDENTS!E:E,"Active") -> 102 | C6: =IFERROR(COUNTIF(ATTENDANCE_LOG!$G:$G,"Present")/(COUNTIF(ATTENDANCE_LOG!$G:$G,"Present")+COUNTIF(ATTENDANCE_LOG!$G:$G,"Absent")),0) -> 0.86387518 | E6: =IFERROR(__xludf.DUMMYFUNCTION("(A6+A9+C9)+COUNTUNIQUE(STUDENTS!A2:A309)-COUNTUNIQUE(STUDENTS!A2:A309)"),308.0) -> 308 | G6: =COUNTIF(STUDENTS!L:L,"✅ Completed") -> 106 | I6: =IFERROR(__xludf.DUMMYFUNCTION("COUNTUNIQUE(STUDENTS!A2:A309)"),308.0) -> 308 | J6: =A6+A9+C9 -> 308
A7: =" out of "&(COUNTIF(STUDENTS!E:E,"Active")+COUNTIF(STUDENTS!E:E,"Inactive")+COUNTIF(STUDENTS!E:E,"Waiting for class"))&" total" -> out of 308 total | C7: =COUNTIF(ATTENDANCE_LOG!G:G,"Present")&" / "&(COUNTIF(ATTENDANCE_LOG!G:G,"Present")+COUNTIF(ATTENDANCE_LOG!G:G,"Absent"))&" sessions" -> 5426 / 6281 sessions
A8: INACTIVE | C8: WAITING FOR CLASS | E8: ⚠ Check | G8: ❌ Dropped
A9: =COUNTIF(STUDENTS!E:E,"Inactive") -> 195 | C9: =COUNTIF(STUDENTS!E:E,"Waiting for class") -> 11 | E9: =COUNTIF(STUDENTS!$L:$L,"⚠ Check") -> 21 | G9: =COUNTIF(STUDENTS!$L:$L,"❌ Dropped") -> 89
A10: completed or stopped | C10: pending placement | E10: flagged for follow-up
A12: ▎ SECTION 2 — ACTIVE STUDENTS BY COURSE | J12: 304 | K12: =J12/1200 -> 0.25333333
A13: Course Name | B13: Active | C13: Inactive | D13: Waiting | E13: Total | F13: % of Active | G13: Bar | J13: 105 | K13: =J13/1200 -> 0.0875
A14: Communication 1 | B14: =COUNTIFS(STUDENTS!G:G,A14,STUDENTS!E:E,"Active") -> 33 | C14: =COUNTIFS(STUDENTS!G:G,A14,STUDENTS!E:E,"Inactive") -> 94 | D14: =COUNTIFS(STUDENTS!G:G,A14,STUDENTS!E:E,"Waiting for class") -> 4 | E14: =B14+C14+D14 -> 131 | F14: =IFERROR(B14/$B$20,0) -> 0.32352941 | G14: =IF($B$20=0,"",REPT("█",ROUND(B14/MAX($B$14:$B$19)*20,0))) -> ████████████████████ | J14: =J12-J13 -> 199 | K14: =J14/1200 -> 0.16583333
A15: Communication 2 | B15: =COUNTIFS(STUDENTS!G:G,A15,STUDENTS!E:E,"Active") -> 15 | C15: =COUNTIFS(STUDENTS!G:G,A15,STUDENTS!E:E,"Inactive") -> 75 | D15: =COUNTIFS(STUDENTS!G:G,A15,STUDENTS!E:E,"Waiting for class") -> 7 | E15: =B15+C15+D15 -> 97 | F15: =IFERROR(B15/$B$20,0) -> 0.14705882 | G15: =IF($B$20=0,"",REPT("█",ROUND(B15/MAX($B$14:$B$19)*20,0))) -> █████████
A16: Communication 3 | B16: =COUNTIFS(STUDENTS!G:G,A16,STUDENTS!E:E,"Active") -> 14 | C16: =COUNTIFS(STUDENTS!G:G,A16,STUDENTS!E:E,"Inactive") -> 7 | D16: =COUNTIFS(STUDENTS!G:G,A16,STUDENTS!E:E,"Waiting for class") -> 0 | E16: =B16+C16+D16 -> 21 | F16: =IFERROR(B16/$B$20,0) -> 0.1372549 | G16: =IF($B$20=0,"",REPT("█",ROUND(B16/MAX($B$14:$B$19)*20,0))) -> ████████
A17: Business English | B17: =COUNTIFS(STUDENTS!G:G,A17,STUDENTS!E:E,"Active") -> 16 | C17: =COUNTIFS(STUDENTS!G:G,A17,STUDENTS!E:E,"Inactive") -> 12 | D17: =COUNTIFS(STUDENTS!G:G,A17,STUDENTS!E:E,"Waiting for class") -> 0 | E17: =B17+C17+D17 -> 28 | F17: =IFERROR(B17/$B$20,0) -> 0.15686275 | G17: =IF($B$20=0,"",REPT("█",ROUND(B17/MAX($B$14:$B$19)*20,0))) -> ██████████
A18: Foundation | B18: =COUNTIFS(STUDENTS!G:G,A18,STUDENTS!E:E,"Active") -> 21 | C18: =COUNTIFS(STUDENTS!G:G,A18,STUDENTS!E:E,"Inactive") -> 7 | D18: =COUNTIFS(STUDENTS!G:G,A18,STUDENTS!E:E,"Waiting for class") -> 0 | E18: =B18+C18+D18 -> 28 | F18: =IFERROR(B18/$B$20,0) -> 0.20588235 | G18: =IF($B$20=0,"",REPT("█",ROUND(B18/MAX($B$14:$B$19)*20,0))) -> █████████████
A19: Extension of Foundation | B19: =COUNTIFS(STUDENTS!G:G,A19,STUDENTS!E:E,"Active") -> 3 | C19: =COUNTIFS(STUDENTS!G:G,A19,STUDENTS!E:E,"Inactive") -> 0 | D19: =COUNTIFS(STUDENTS!G:G,A19,STUDENTS!E:E,"Waiting for class") -> 0 | E19: =B19+C19+D19 -> 3 | F19: =IFERROR(B19/$B$20,0) -> 0.029411765 | G19: =IF($B$20=0,"",REPT("█",ROUND(B19/MAX($B$14:$B$19)*20,0))) -> ██
A20: TOTAL | B20: =SUM(B14:B19) -> 102 | C20: =SUM(C14:C19) -> 195 | D20: =SUM(D14:D19) -> 11 | E20: =SUM(E14:E19) -> 308 | F20: =IFERROR(B20/E20,0) -> 0.33116883
A22: ▎ SECTION 3 — WHY STUDENTS GO INACTIVE
A23: Drop Reason | B23: Count | C23: % | E23: Inactive Classification | F23: Count | G23: %
A24: High workload | B24: =COUNTIF(STUDENTS!N:N,A24) -> 102 | C24: =IFERROR(B24/SUM($B$24:$B$29),0) -> 0.52849741 | E24: Completed (no continuation) | F24: =COUNTIF(STUDENTS!M:M,E24) -> 106 | G24: =IFERROR(F24/SUM($F$24:$F$27),0) -> 0.54358974
A25: Prefer different learning format | B25: =COUNTIF(STUDENTS!N:N,A25) -> 25 | C25: =IFERROR(B25/SUM($B$24:$B$29),0) -> 0.12953368 | E25: Discontinued mid-course | F25: =COUNTIF(STUDENTS!M:M,E25) -> 89 | G25: =IFERROR(F25/SUM($F$24:$F$27),0) -> 0.45641026
A26: Learning goal achieved | B26: =COUNTIF(STUDENTS!N:N,A26) -> 42 | C26: =IFERROR(B26/SUM($B$24:$B$29),0) -> 0.21761658 | E26: Business EL, chờ xếp lớp | F26: =COUNTIF(STUDENTS!M:M,E26) -> 0 | G26: =IFERROR(F26/SUM($F$24:$F$27),0) -> 0
A27: Team restructuring | B27: =COUNTIF(STUDENTS!N:N,A27) -> 5 | C27: =IFERROR(B27/SUM($B$24:$B$29),0) -> 0.025906736 | E27: BE, chờ xếp lớp | F27: =COUNTIF(STUDENTS!M:M,E27) -> 0 | G27: =IFERROR(F27/SUM($F$24:$F$27),0) -> 0
A28: Maternity leave | B28: =COUNTIF(STUDENTS!N:N,A28) -> 3 | C28: =IFERROR(B28/SUM($B$24:$B$29),0) -> 0.015544041
A29: Resign | B29: =COUNTIF(STUDENTS!N:N,A29) -> 16 | C29: =IFERROR(B29/SUM($B$24:$B$29),0) -> 0.082901554
A30: TOTAL | B30: =SUM(B24:B29) -> 193 | C30: =sum(C24:D29) -> 1 | E30: TOTAL | F30: =SUM(F24:F28) -> 195
A32: ▎ SECTION 4 — CLASS PROGRESS
A33: Class Code | B33: Course Name | C33: PIC | D33: Sessions Done | E33: Expected | F33: Progress % | G33: Progress Bar | H33: Status
A34: EL001 | B34: Communication 1 | C34: =IFERROR(VLOOKUP(A34,PIC!A:B,2,0),"") -> Anh Vu | D34: =IFERROR(MAXIFS(ATTENDANCE_LOG!E:E,ATTENDANCE_LOG!A:A,A34,ATTENDANCE_LOG!B:B,B34),0) -> 10 | E34: =IFERROR(VLOOKUP(B34,COURSE_PLAN!A:B,2,0),0) -> 10 | F34: =IFERROR(MIN(D34/E34,1),0) -> 1 | G34: =IF(E34=0,"—",REPT("█",ROUND(F34*20,0))&REPT("░",20-ROUND(F34*20,0))) -> ████████████████████ | H34: =IF(E34=0,"No plan",IF(F34>=1,"✅ Done",IF(F34>=0.75,"🟢 Almost",IF(F34>=0.25,"🔄 In progress",IF(F34>0,"🟡 Just started","⚪ Not started"))))) -> ✅ Done
A35: EL001 | B35: Communication 2 | C35: =IFERROR(VLOOKUP(A35,PIC!A:B,2,0),"") -> Anh Vu | D35: =IFERROR(MAXIFS(ATTENDANCE_LOG!E:E,ATTENDANCE_LOG!A:A,A35,ATTENDANCE_LOG!B:B,B35),0) -> 16 | E35: =IFERROR(VLOOKUP(B35,COURSE_PLAN!A:B,2,0),0) -> 16 | F35: =IFERROR(MIN(D35/E35,1),0) -> 1 | G35: =IF(E35=0,"—",REPT("█",ROUND(F35*20,0))&REPT("░",20-ROUND(F35*20,0))) -> ████████████████████ | H35: =IF(E35=0,"No plan",IF(F35>=1,"✅ Done",IF(F35>=0.75,"🟢 Almost",IF(F35>=0.25,"🔄 In progress",IF(F35>0,"🟡 Just started","⚪ Not started"))))) -> ✅ Done
A36: EL002 | B36: Communication 1 | C36: =IFERROR(VLOOKUP(A36,PIC!A:B,2,0),"") -> Buu Do 1 | D36: =IFERROR(MAXIFS(ATTENDANCE_LOG!E:E,ATTENDANCE_LOG!A:A,A36,ATTENDANCE_LOG!B:B,B36),0) -> 10 | E36: =IFERROR(VLOOKUP(B36,COURSE_PLAN!A:B,2,0),0) -> 10 | F36: =IFERROR(MIN(D36/E36,1),0) -> 1 | G36: =IF(E36=0,"—",REPT("█",ROUND(F36*20,0))&REPT("░",20-ROUND(F36*20,0))) -> ████████████████████ | H36: =IF(E36=0,"No plan",IF(F36>=1,"✅ Done",IF(F36>=0.75,"🟢 Almost",IF(F36>=0.25,"🔄 In progress",IF(F36>0,"🟡 Just started","⚪ Not started"))))) -> ✅ Done
A37: EL003 | B37: Communication 1 | C37: =IFERROR(VLOOKUP(A37,PIC!A:B,2,0),"") -> Buu Do 2 | D37: =IFERROR(MAXIFS(ATTENDANCE_LOG!E:E,ATTENDANCE_LOG!A:A,A37,ATTENDANCE_LOG!B:B,B37),0) -> 10 | E37: =IFERROR(VLOOKUP(B37,COURSE_PLAN!A:B,2,0),0) -> 10 | F37: =IFERROR(MIN(D37/E37,1),0) -> 1 | G37: =IF(E37=0,"—",REPT("█",ROUND(F37*20,0))&REPT("░",20-ROUND(F37*20,0))) -> ████████████████████ | H37: =IF(E37=0,"No plan",IF(F37>=1,"✅ Done",IF(F37>=0.75,"🟢 Almost",IF(F37>=0.25,"🔄 In progress",IF(F37>0,"🟡 Just started","⚪ Not started"))))) -> ✅ Done
A38: EL004 | B38: Communication 1 | C38: =IFERROR(VLOOKUP(A38,PIC!A:B,2,0),"") -> Cuong Nguyen | D38: =IFERROR(MAXIFS(ATTENDANCE_LOG!E:E,ATTENDANCE_LOG!A:A,A38,ATTENDANCE_LOG!B:B,B38),0) -> 10 | E38: =IFERROR(VLOOKUP(B38,COURSE_PLAN!A:B,2,0),0) -> 10 | F38: =IFERROR(MIN(D38/E38,1),0) -> 1 | G38: =IF(E38=0,"—",REPT("█",ROUND(F38*20,0))&REPT("░",20-ROUND(F38*20,0))) -> ████████████████████ | H38: =IF(E38=0,"No plan",IF(F38>=1,"✅ Done",IF(F38>=0.75,"🟢 Almost",IF(F38>=0.25,"🔄 In progress",IF(F38>0,"🟡 Just started","⚪ Not started"))))) -> ✅ Done
A39: EL004 | B39: Communication 2 | C39: =IFERROR(VLOOKUP(A39,PIC!A:B,2,0),"") -> Cuong Nguyen | D39: =IFERROR(MAXIFS(ATTENDANCE_LOG!E:E,ATTENDANCE_LOG!A:A,A39,ATTENDANCE_LOG!B:B,B39),0) -> 16 | E39: =IFERROR(VLOOKUP(B39,COURSE_PLAN!A:B,2,0),0) -> 16 | F39: =IFERROR(MIN(D39/E39,1),0) -> 1 | G39: =IF(E39=0,"—",REPT("█",ROUND(F39*20,0))&REPT("░",20-ROUND(F39*20,0))) -> ████████████████████ | H39: =IF(E39=0,"No plan",IF(F39>=1,"✅ Done",IF(F39>=0.75,"🟢 Almost",IF(F39>=0.25,"🔄 In progress",IF(F39>0,"🟡 Just started","⚪ Not started"))))) -> ✅ Done
A40: EL005 | B40: Communication 1 | C40: =IFERROR(VLOOKUP(A40,PIC!A:B,2,0),"") -> Duc Nguyen | D40: =IFERROR(MAXIFS(ATTENDANCE_LOG!E:E,ATTENDANCE_LOG!A:A,A40,ATTENDANCE_LOG!B:B,B40),0) -> 10 | E40: =IFERROR(VLOOKUP(B40,COURSE_PLAN!A:B,2,0),0) -> 10 | F40: =IFERROR(MIN(D40/E40,1),0) -> 1 | G40: =IF(E40=0,"—",REPT("█",ROUND(F40*20,0))&REPT("░",20-ROUND(F40*20,0))) -> ████████████████████ | H40: =IF(E40=0,"No plan",IF(F40>=1,"✅ Done",IF(F40>=0.75,"🟢 Almost",IF(F40>=0.25,"🔄 In progress",IF(F40>0,"🟡 Just started","⚪ Not started"))))) -> ✅ Done
A41: EL006 | B41: Communication 1 | C41: =IFERROR(VLOOKUP(A41,PIC!A:B,2,0),"") -> Dat Nguyen | D41: =IFERROR(MAXIFS(ATTENDANCE_LOG!E:E,ATTENDANCE_LOG!A:A,A41,ATTENDANCE_LOG!B:B,B41),0) -> 10 | E41: =IFERROR(VLOOKUP(B41,COURSE_PLAN!A:B,2,0),0) -> 10 | F41: =IFERROR(MIN(D41/E41,1),0) -> 1 | G41: =IF(E41=0,"—",REPT("█",ROUND(F41*20,0))&REPT("░",20-ROUND(F41*20,0))) -> ████████████████████ | H41: =IF(E41=0,"No plan",IF(F41>=1,"✅ Done",IF(F41>=0.75,"🟢 Almost",IF(F41>=0.25,"🔄 In progress",IF(F41>0,"🟡 Just started","⚪ Not started"))))) -> ✅ Done
A42: EL007 | B42: Communication 1 | C42: =IFERROR(VLOOKUP(A42,PIC!A:B,2,0),"") -> Nhat Nguyen | D42: =IFERROR(MAXIFS(ATTENDANCE_LOG!E:E,ATTENDANCE_LOG!A:A,A42,ATTENDANCE_LOG!B:B,B42),0) -> 12 | E42: =IFERROR(VLOOKUP(B42,COURSE_PLAN!A:B,2,0),0) -> 10 | F42: =IFERROR(MIN(D42/E42,1),0) -> 1 | G42: =IF(E42=0,"—",REPT("█",ROUND(F42*20,0))&REPT("░",20-ROUND(F42*20,0))) -> ████████████████████ | H42: =IF(E42=0,"No plan",IF(F42>=1,"✅ Done",IF(F42>=0.75,"🟢 Almost",IF(F42>=0.25,"🔄 In progress",IF(F42>0,"🟡 Just started","⚪ Not started"))))) -> ✅ Done
A43: EL007 | B43: Communication 2 | C43: =IFERROR(VLOOKUP(A43,PIC!A:B,2,0),"") -> Nhat Nguyen | D43: =IFERROR(MAXIFS(ATTENDANCE_LOG!E:E,ATTENDANCE_LOG!A:A,A43,ATTENDANCE_LOG!B:B,B43),0) -> 16 | E43: =IFERROR(VLOOKUP(B43,COURSE_PLAN!A:B,2,0),0) -> 16 | F43: =IFERROR(MIN(D43/E43,1),0) -> 1 | G43: =IF(E43=0,"—",REPT("█",ROUND(F43*20,0))&REPT("░",20-ROUND(F43*20,0))) -> ████████████████████ | H43: =IF(E43=0,"No plan",IF(F43>=1,"✅ Done",IF(F43>=0.75,"🟢 Almost",IF(F43>=0.25,"🔄 In progress",IF(F43>0,"🟡 Just started","⚪ Not started"))))) -> ✅ Done
A44: EL008 | B44: Communication 1 | C44: =IFERROR(VLOOKUP(A44,PIC!A:B,2,0),"") -> Hung Nguyen | D44: =IFERROR(MAXIFS(ATTENDANCE_LOG!E:E,ATTENDANCE_LOG!A:A,A44,ATTENDANCE_LOG!B:B,B44),0) -> 10 | E44: =IFERROR(VLOOKUP(B44,COURSE_PLAN!A:B,2,0),0) -> 10 | F44: =IFERROR(MIN(D44/E44,1),0) -> 1 | G44: =IF(E44=0,"—",REPT("█",ROUND(F44*20,0))&REPT("░",20-ROUND(F44*20,0))) -> ████████████████████ | H44: =IF(E44=0,"No plan",IF(F44>=1,"✅ Done",IF(F44>=0.75,"🟢 Almost",IF(F44>=0.25,"🔄 In progress",IF(F44>0,"🟡 Just started","⚪ Not started"))))) -> ✅ Done
...

Sheet DATE_ANOMALIES
A1: Loại | B1: Cell | C1: Class/Course | D1: Chi tiết
A2: B - Typo năm | B2: H189 | C2: EL020/Communication 1 | D2: Ghi 12/30/2024 (năm 2024) — đa số bạn cùng buổi ghi năm 2025
A3: B - Typo năm | B3: H192 | C3: EL020/Communication 1 | D3: Ghi 12/30/2024 (năm 2024) — đa số bạn cùng buổi ghi năm 2025
A4: B - Typo năm | B4: H195 | C4: EL020/Communication 1 | D4: Ghi 12/30/2024 (năm 2024) — đa số bạn cùng buổi ghi năm 2025

Sheet STUDENTS
A1: Emp Code | B1: Full Name | C1: BU | D1: ROLE | E1: Status | F1: PIC | G1: Current Course | H1: Entrance Level | I1: Current Level | J1: Last Active Date | K1: Days Since Active | L1: Drop Flag (<30 days is safe) | M1: Define of drop (not inc. resign) | N1: Drop reason | O1: Remark | Q1: Latest Class Code | R1: Latest Course Name | S1: Entrance Numeric | T1: Current Numeric | U1: Entrance Group (1/2/3/4) | V1: Current Group (1/2/3/4) | W1: Progress Category
A2: 193445 | B2: HUỲNH THỊ BẢO YẾN | C2: =IFERROR(__xludf.DUMMYFUNCTION("arrayformula(VLOOKUP(to_Text(A2),to_Text(sheet2!$A$1:M1005),13,0))"),"MOC") -> MOC | D2: =IFERROR(__xludf.DUMMYFUNCTION("arrayformula(VLOOKUP(to_Text(A2),to_Text(sheet2!$A$1:M1005),12,0))"),"QC") -> QC | E2: =IF(OR(L2="✅ Completed",L2="❌ Dropped"),"Inactive",IF(M2="Waiting for class","Waiting for class","Active")) -> Inactive | F2: {=IFERROR( INDEX(ATTENDANCE_INPUT!D:D, MATCH(1, (ATTENDANCE_INPUT!A:A=A2) * (ATTENDANCE_INPUT!W:W=MAXIFS(ATTENDANCE_INPUT!W:W, ATTENDANCE_INPUT!A:A, A2)), 0)), "")} -> Anh Ha | G2: {=IFERROR( INDEX(ATTENDANCE_INPUT!E:E, MATCH(1, (ATTENDANCE_INPUT!A:A=A2) * (ATTENDANCE_INPUT!W:W=MAXIFS(ATTENDANCE_INPUT!W:W, ATTENDANCE_INPUT!A:A, A2)), 0)), "")} -> Communication 2 | H2: {=IF(ISNA(MATCH(A2,sheet2!A:A,0)),"⏳ Chưa test",IFERROR(INDEX(LEVEL_HELPER!A:A,MATCH(INDEX(sheet2!N:N,MATCH(A2,sheet2!A:A,0)),LEVEL_HELPER!B:B,0)),"⏳ Chưa test"))} -> Beginner | I2: {=IF(ISNA(MATCH(A2,sheet2!A:A,0)),H2,IF(INDEX(sheet2!O:O,MATCH(A2,sheet2!A:A,0))>0,IFERROR(INDEX(LEVEL_HELPER!A:A,MATCH(INDEX(sheet2!O:O,MATCH(A2,sheet2!A:A,0)),LEVEL_HELPER!B:B,0)),H2),H2))} -> Pre-Intermediate 1 | J2: =IFERROR(MAXIFS(ATTENDANCE_LOG!F:F, ATTENDANCE_LOG!C:C, A2&"", ATTENDANCE_LOG!G:G, "Present"), "") -> 46106.542 | K2: =IF(J2="", "", TODAY() - J2) -> 106.45833 | L2: =IF(M2="Completed (no continuation)","✅ Completed",IF(M2="Discontinued mid-course","❌ Dropped",IF(AND(ISNUMBER(K2),K2>=30),"⚠ Check",""))) -> ✅ Completed | M2: Completed (no continuation) | N2: Learning goal achieved | P2: =IFERROR(__xludf.DUMMYFUNCTION("IFERROR(COUNTUNIQUEIFS(ATTENDANCE_LOG!B:B,ATTENDANCE_LOG!C:C,A2),0)"),2.0) -> 2 | Q2: {=IFERROR(INDEX(ATTENDANCE_LOG!A:A,MATCH(1,(ATTENDANCE_LOG!C:C=A2)*(ATTENDANCE_LOG!F:F=MAXIFS(ATTENDANCE_LOG!F:F,ATTENDANCE_LOG!C:C,A2)),0)),"")} -> EL033 | R2: {=IFERROR(INDEX(ATTENDANCE_LOG!B:B,MATCH(1,(ATTENDANCE_LOG!C:C=A2)*(ATTENDANCE_LOG!F:F=MAXIFS(ATTENDANCE_LOG!F:F,ATTENDANCE_LOG!C:C,A2)),0)),"")} -> Communication 2 | S2: =IFERROR(VLOOKUP(H2, LEVEL_HELPER!A:B, 2, 0), 0) -> 1 | T2: =IFERROR(VLOOKUP(I2, LEVEL_HELPER!A:B, 2, 0), 0) -> 3 | U2: =IF(S2="",0,IF(S2<=2,1,IF(S2<=4,2,IF(S2<=5.5,3,4)))) -> 1 | V2: =IF(T2="",0,IF(T2<=2,1,IF(T2<=4,2,IF(T2<=5.5,3,4)))) -> 2 | W2: =IF(OR(H2="", H2="Not Placement"), "Not tested yet", IF(V2<U2, "Regressed", IF(V2=U2, IF(T2>S2, "Minor Improvement", "No Progress"), IF(V2-U2=1, "Lv"&U2&"→Lv"&V2, "Lv"&U2&"→Lv"&V2&" (multi)")))) -> Lv1→Lv2
A3: 213815 | B3: HUỲNH TRẦN HẢI LONG | C3: =IFERROR(__xludf.DUMMYFUNCTION("arrayformula(VLOOKUP(to_Text(A3),to_Text(sheet2!$A$1:M1005),13,0))"),"MOC") -> MOC | D3: =IFERROR(__xludf.DUMMYFUNCTION("arrayformula(VLOOKUP(to_Text(A3),to_Text(sheet2!$A$1:M1005),12,0))"),"DEV") -> DEV | E3: =IF(OR(L3="✅ Completed",L3="❌ Dropped"),"Inactive",IF(M3="Waiting for class","Waiting for class","Active")) -> Inactive | F3: {=IFERROR( INDEX(ATTENDANCE_INPUT!D:D, MATCH(1, (ATTENDANCE_INPUT!A:A=A3) * (ATTENDANCE_INPUT!W:W=MAXIFS(ATTENDANCE_INPUT!W:W, ATTENDANCE_INPUT!A:A, A3)), 0)), "")} -> Anh Ha | G3: {=IFERROR( INDEX(ATTENDANCE_INPUT!E:E, MATCH(1, (ATTENDANCE_INPUT!A:A=A3) * (ATTENDANCE_INPUT!W:W=MAXIFS(ATTENDANCE_INPUT!W:W, ATTENDANCE_INPUT!A:A, A3)), 0)), "")} -> Communication 2 | H3: {=IF(ISNA(MATCH(A3,sheet2!A:A,0)),"⏳ Chưa test",IFERROR(INDEX(LEVEL_HELPER!A:A,MATCH(INDEX(sheet2!N:N,MATCH(A3,sheet2!A:A,0)),LEVEL_HELPER!B:B,0)),"⏳ Chưa test"))} -> Beginner | I3: {=IF(ISNA(MATCH(A3,sheet2!A:A,0)),H3,IF(INDEX(sheet2!O:O,MATCH(A3,sheet2!A:A,0))>0,IFERROR(INDEX(LEVEL_HELPER!A:A,MATCH(INDEX(sheet2!O:O,MATCH(A3,sheet2!A:A,0)),LEVEL_HELPER!B:B,0)),H3),H3))} -> Pre-Intermediate 1 | J3: =IFERROR(MAXIFS(ATTENDANCE_LOG!F:F, ATTENDANCE_LOG!C:C, A3&"", ATTENDANCE_LOG!G:G, "Present"), "") -> 46106.542 | K3: =IF(J3="", "", TODAY() - J3) -> 106.45833 | L3: =IF(M3="Completed (no continuation)","✅ Completed",IF(M3="Discontinued mid-course","❌ Dropped",IF(AND(ISNUMBER(K3),K3>=30),"⚠ Check",""))) -> ✅ Completed | M3: Completed (no continuation) | N3: Learning goal achieved | P3: =IFERROR(__xludf.DUMMYFUNCTION("IFERROR(COUNTUNIQUEIFS(ATTENDANCE_LOG!B:B,ATTENDANCE_LOG!C:C,A3),0)"),2.0) -> 2 | Q3: {=IFERROR(INDEX(ATTENDANCE_LOG!A:A,MATCH(1,(ATTENDANCE_LOG!C:C=A3)*(ATTENDANCE_LOG!F:F=MAXIFS(ATTENDANCE_LOG!F:F,ATTENDANCE_LOG!C:C,A3)),0)),"")} -> EL033 | R3: {=IFERROR(INDEX(ATTENDANCE_LOG!B:B,MATCH(1,(ATTENDANCE_LOG!C:C=A3)*(ATTENDANCE_LOG!F:F=MAXIFS(ATTENDANCE_LOG!F:F,ATTENDANCE_LOG!C:C,A3)),0)),"")} -> Communication 2 | S3: =IFERROR(VLOOKUP(H3, LEVEL_HELPER!A:B, 2, 0), 0) -> 1 | T3: =IFERROR(VLOOKUP(I3, LEVEL_HELPER!A:B, 2, 0), 0) -> 3 | U3: =IF(S3="",0,IF(S3<=2,1,IF(S3<=4,2,IF(S3<=5.5,3,4)))) -> 1 | V3: =IF(T3="",0,IF(T3<=2,1,IF(T3<=4,2,IF(T3<=5.5,3,4)))) -> 2 | W3: =IF(OR(H3="", H3="Not Placement"), "Not tested yet", IF(V3<U3, "Regressed", IF(V3=U3, IF(T3>S3, "Minor Improvement", "No Progress"), IF(V3-U3=1, "Lv"&U3&"→Lv"&V3, "Lv"&U3&"→Lv"&V3&" (multi)")))) -> Lv1→Lv2
A4: 213914 | B4: NGUYỄN TẤN PHÁT | C4: =IFERROR(__xludf.DUMMYFUNCTION("arrayformula(VLOOKUP(to_Text(A4),to_Text(sheet2!$A$1:M1005),13,0))"),"MOC") -> MOC | D4: =IFERROR(__xludf.DUMMYFUNCTION("arrayformula(VLOOKUP(to_Text(A4),to_Text(sheet2!$A$1:M1005),12,0))"),"DEV") -> DEV | E4: =IF(OR(L4="✅ Completed",L4="❌ Dropped"),"Inactive",IF(M4="Waiting for class","Waiting for class","Active")) -> Inactive | F4: {=IFERROR( INDEX(ATTENDANCE_INPUT!D:D, MATCH(1, (ATTENDANCE_INPUT!A:A=A4) * (ATTENDANCE_INPUT!W:W=MAXIFS(ATTENDANCE_INPUT!W:W, ATTENDANCE_INPUT!A:A, A4)), 0)), "")} -> Anh Ha | G4: {=IFERROR( INDEX(ATTENDANCE_INPUT!E:E, MATCH(1, (ATTENDANCE_INPUT!A:A=A4) * (ATTENDANCE_INPUT!W:W=MAXIFS(ATTENDANCE_INPUT!W:W, ATTENDANCE_INPUT!A:A, A4)), 0)), "")} -> Communication 2 | H4: {=IF(ISNA(MATCH(A4,sheet2!A:A,0)),"⏳ Chưa test",IFERROR(INDEX(LEVEL_HELPER!A:A,MATCH(INDEX(sheet2!N:N,MATCH(A4,sheet2!A:A,0)),LEVEL_HELPER!B:B,0)),"⏳ Chưa test"))} -> Beginner | I4: {=IF(ISNA(MATCH(A4,sheet2!A:A,0)),H4,IF(INDEX(sheet2!O:O,MATCH(A4,sheet2!A:A,0))>0,IFERROR(INDEX(LEVEL_HELPER!A:A,MATCH(INDEX(sheet2!O:O,MATCH(A4,sheet2!A:A,0)),LEVEL_HELPER!B:B,0)),H4),H4))} -> Pre-Intermediate 2 | J4: =IFERROR(MAXIFS(ATTENDANCE_LOG!F:F, ATTENDANCE_LOG!C:C, A4&"", ATTENDANCE_LOG!G:G, "Present"), "") -> 46106.542 | K4: =IF(J4="", "", TODAY() - J4) -> 106.45833 | L4: =IF(M4="Completed (no continuation)","✅ Completed",IF(M4="Discontinued mid-course","❌ Dropped",IF(AND(ISNUMBER(K4),K4>=30),"⚠ Check",""))) -> ✅ Completed | M4: Completed (no continuation) | N4: Learning goal achieved | O4: Đã complete Com1, stop 5/2025 và giờ quay lại học | P4: =IFERROR(__xludf.DUMMYFUNCTION("IFERROR(COUNTUNIQUEIFS(ATTENDANCE_LOG!B:B,ATTENDANCE_LOG!C:C,A4),0)"),2.0) -> 2 | Q4: {=IFERROR(INDEX(ATTENDANCE_LOG!A:A,MATCH(1,(ATTENDANCE_LOG!C:C=A4)*(ATTENDANCE_LOG!F:F=MAXIFS(ATTENDANCE_LOG!F:F,ATTENDANCE_LOG!C:C,A4)),0)),"")} -> EL033 | R4: {=IFERROR(INDEX(ATTENDANCE_LOG!B:B,MATCH(1,(ATTENDANCE_LOG!C:C=A4)*(ATTENDANCE_LOG!F:F=MAXIFS(ATTENDANCE_LOG!F:F,ATTENDANCE_LOG!C:C,A4)),0)),"")} -> Communication 2 | S4: =IFERROR(VLOOKUP(H4, LEVEL_HELPER!A:B, 2, 0), 0) -> 1 | T4: =IFERROR(VLOOKUP(I4, LEVEL_HELPER!A:B, 2, 0), 0) -> 3.5 | U4: =IF(S4="",0,IF(S4<=2,1,IF(S4<=4,2,IF(S4<=5.5,3,4)))) -> 1 | V4: =IF(T4="",0,IF(T4<=2,1,IF(T4<=4,2,IF(T4<=5.5,3,4)))) -> 2 | W4: =IF(OR(H4="", H4="Not Placement"), "Not tested yet", IF(V4<U4, "Regressed", IF(V4=U4, IF(T4>S4, "Minor Improvement", "No Progress"), IF(V4-U4=1, "Lv"&U4&"→Lv"&V4, "Lv"&U4&"→Lv"&V4&" (multi)")))) -> Lv1→Lv2 | Y4: 247311 | Z4: High workload / Can't arrange time | AA4: High workload | AC4: 267126 | AD4: =countif($A$2:$A1005,AC4) -> 0
A5: 213968 | B5: NGUYỄN THỊ HOÀNG OANH | C5: =IFERROR(__xludf.DUMMYFUNCTION("arrayformula(VLOOKUP(to_Text(A5),to_Text(sheet2!$A$1:M1005),13,0))"),"MOC") -> MOC | D5: =IFERROR(__xludf.DUMMYFUNCTION("arrayformula(VLOOKUP(to_Text(A5),to_Text(sheet2!$A$1:M1005),12,0))"),"QC") -> QC | E5: =IF(OR(L5="✅ Completed",L5="❌ Dropped"),"Inactive",IF(M5="Waiting for class","Waiting for class","Active")) -> Inactive | F5: {=IFERROR( INDEX(ATTENDANCE_INPUT!D:D, MATCH(1, (ATTENDANCE_INPUT!A:A=A5) * (ATTENDANCE_INPUT!W:W=MAXIFS(ATTENDANCE_INPUT!W:W, ATTENDANCE_INPUT!A:A, A5)), 0)), "")} -> Anh Ha | G5: {=IFERROR( INDEX(ATTENDANCE_INPUT!E:E, MATCH(1, (ATTENDANCE_INPUT!A:A=A5) * (ATTENDANCE_INPUT!W:W=MAXIFS(ATTENDANCE_INPUT!W:W, ATTENDANCE_INPUT!A:A, A5)), 0)), "")} -> Communication 2 | H5: {=IF(ISNA(MATCH(A5,sheet2!A:A,0)),"⏳ Chưa test",IFERROR(INDEX(LEVEL_HELPER!A:A,MATCH(INDEX(sheet2!N:N,MATCH(A5,sheet2!A:A,0)),LEVEL_HELPER!B:B,0)),"⏳ Chưa test"))} -> Beginner | I5: {=IF(ISNA(MATCH(A5,sheet2!A:A,0)),H5,IF(INDEX(sheet2!O:O,MATCH(A5,sheet2!A:A,0))>0,IFERROR(INDEX(LEVEL_HELPER!A:A,MATCH(INDEX(sheet2!O:O,MATCH(A5,sheet2!A:A,0)),LEVEL_HELPER!B:B,0)),H5),H5))} -> Beginner 2 | J5: =IFERROR(MAXIFS(ATTENDANCE_LOG!F:F, ATTENDANCE_LOG!C:C, A5&"", ATTENDANCE_LOG!G:G, "Present"), "") -> 46050.417 | K5: =IF(J5="", "", TODAY() - J5) -> 162.58333 | L5: =IF(M5="Completed (no continuation)","✅ Completed",IF(M5="Discontinued mid-course","❌ Dropped",IF(AND(ISNUMBER(K5),K5>=30),"⚠ Check",""))) -> ✅ Completed | M5: Completed (no continuation) | N5: Learning goal achieved | P5: =IFERROR(__xludf.DUMMYFUNCTION("IFERROR(COUNTUNIQUEIFS(ATTENDANCE_LOG!B:B,ATTENDANCE_LOG!C:C,A5),0)"),2.0) -> 2 | Q5: {=IFERROR(INDEX(ATTENDANCE_LOG!A:A,MATCH(1,(ATTENDANCE_LOG!C:C=A5)*(ATTENDANCE_LOG!F:F=MAXIFS(ATTENDANCE_LOG!F:F,ATTENDANCE_LOG!C:C,A5)),0)),"")} -> EL033 | R5: {=IFERROR(INDEX(ATTENDANCE_LOG!B:B,MATCH(1,(ATTENDANCE_LOG!C:C=A5)*(ATTENDANCE_LOG!F:F=MAXIFS(ATTENDANCE_LOG!F:F,ATTENDANCE_LOG!C:C,A5)),0)),"")} -> Communication 2 | S5: =IFERROR(VLOOKUP(H5, LEVEL_HELPER!A:B, 2, 0), 0) -> 1 | T5: =IFERROR(VLOOKUP(I5, LEVEL_HELPER!A:B, 2, 0), 0) -> 1.5 | U5: =IF(S5="",0,IF(S5<=2,1,IF(S5<=4,2,IF(S5<=5.5,3,4)))) -> 1 | V5: =IF(T5="",0,IF(T5<=2,1,IF(T5<=4,2,IF(T5<=5.5,3,4)))) -> 1 | W5: =IF(OR(H5="", H5="Not Placement"), "Not tested yet", IF(V5<U5, "Regressed", IF(V5=U5, IF(T5>S5, "Minor Improvement", "No Progress"), IF(V5-U5=1, "Lv"&U5&"→Lv"&V5, "Lv"&U5&"→Lv"&V5&" (multi)")))) -> Minor Improvement | Y5: 247324 | Z5: Above the team's level | AA5: Above the team's level | AC5: 247045 | AD5: =countif($A$2:$A1006,AC5) -> 0
A6: 213861 | B6: TRẦN QUANG ĐẠO | C6: =IFERROR(__xludf.DUMMYFUNCTION("arrayformula(VLOOKUP(to_Text(A6),to_Text(sheet2!$A$1:M1005),13,0))"),"MOC") -> MOC | D6: =IFERROR(__xludf.DUMMYFUNCTION("arrayformula(VLOOKUP(to_Text(A6),to_Text(sheet2!$A$1:M1005),12,0))"),"DEV") -> DEV | E6: =IF(OR(L6="✅ Completed",L6="❌ Dropped"),"Inactive",IF(M6="Waiting for class","Waiting for class","Active")) -> Inactive | F6: {=IFERROR( INDEX(ATTENDANCE_INPUT!D:D, MATCH(1, (ATTENDANCE_INPUT!A:A=A6) * (ATTENDANCE_INPUT!W:W=MAXIFS(ATTENDANCE_INPUT!W:W, ATTENDANCE_INPUT!A:A, A6)), 0)), "")} -> Anh Ha | G6: {=IFERROR( INDEX(ATTENDANCE_INPUT!E:E, MATCH(1, (ATTENDANCE_INPUT!A:A=A6) * (ATTENDANCE_INPUT!W:W=MAXIFS(ATTENDANCE_INPUT!W:W, ATTENDANCE_INPUT!A:A, A6)), 0)), "")} -> Communication 2 | H6: {=IF(ISNA(MATCH(A6,sheet2!A:A,0)),"⏳ Chưa test",IFERROR(INDEX(LEVEL_HELPER!A:A,MATCH(INDEX(sheet2!N:N,MATCH(A6,sheet2!A:A,0)),LEVEL_HELPER!B:B,0)),"⏳ Chưa test"))} -> Beginner | I6: {=IF(ISNA(MATCH(A6,sheet2!A:A,0)),H6,IF(INDEX(sheet2!O:O,MATCH(A6,sheet2!A:A,0))>0,IFERROR(INDEX(LEVEL_HELPER!A:A,MATCH(INDEX(sheet2!O:O,MATCH(A6,sheet2!A:A,0)),LEVEL_HELPER!B:B,0)),H6),H6))} -> Pre-Intermediate 1 | J6: =IFERROR(MAXIFS(ATTENDANCE_LOG!F:F, ATTENDANCE_LOG!C:C, A6&"", ATTENDANCE_LOG!G:G, "Present"), "") -> 46106.542 | K6: =IF(J6="", "", TODAY() - J6) -> 106.45833 | L6: =IF(M6="Completed (no continuation)","✅ Completed",IF(M6="Discontinued mid-course","❌ Dropped",IF(AND(ISNUMBER(K6),K6>=30),"⚠ Check",""))) -> ✅ Completed | M6: Completed (no continuation) | N6: Learning goal achieved | P6: =IFERROR(__xludf.DUMMYFUNCTION("IFERROR(COUNTUNIQUEIFS(ATTENDANCE_LOG!B:B,ATTENDANCE_LOG!C:C,A6),0)"),2.0) -> 2 | Q6: {=IFERROR(INDEX(ATTENDANCE_LOG!A:A,MATCH(1,(ATTENDANCE_LOG!C:C=A6)*(ATTENDANCE_LOG!F:F=MAXIFS(ATTENDANCE_LOG!F:F,ATTENDANCE_LOG!C:C,A6)),0)),"")} -> EL033 | R6: {=IFERROR(INDEX(ATTENDANCE_LOG!B:B,MATCH(1,(ATTENDANCE_LOG!C:C=A6)*(ATTENDANCE_LOG!F:F=MAXIFS(ATTENDANCE_LOG!F:F,ATTENDANCE_LOG!C:C,A6)),0)),"")} -> Communication 2 | S6: =IFERROR(VLOOKUP(H6, LEVEL_HELPER!A:B, 2, 0), 0) -> 1 | T6: =IFERROR(VLOOKUP(I6, LEVEL_HELPER!A:B, 2, 0), 0) -> 3 | U6: =IF(S6="",0,IF(S6<=2,1,IF(S6<=4,2,IF(S6<=5.5,3,4)))) -> 1 | V6: =IF(T6="",0,IF(T6<=2,1,IF(T6<=4,2,IF(T6<=5.5,3,4)))) -> 2 | W6: =IF(OR(H6="", H6="Not Placement"), "Not tested yet", IF(V6<U6, "Regressed", IF(V6=U6, IF(T6>S6, "Minor Improvement", "No Progress"), IF(V6-U6=1, "Lv"&U6&"→Lv"&V6, "Lv"&U6&"→Lv"&V6&" (multi)")))) -> Lv1→Lv2 | Y6: 247323 | Z6: High workload / Can't arrange time | AA6: High workload | AC6: 247046 | AD6: =countif($A$2:$A1007,AC6) -> 0
A7: 213851 | B7: TRẦN THANH ĐIỀN | C7: =IFERROR(__xludf.DUMMYFUNCTION("arrayformula(VLOOKUP(to_Text(A7),to_Text(sheet2!$A$1:M1005),13,0))"),"MOC") -> MOC | D7: =IFERROR(__xludf.DUMMYFUNCTION("arrayformula(VLOOKUP(to_Text(A7),to_Text(sheet2!$A$1:M1005),12,0))"),"DEV") -> DEV | E7: =IF(OR(L7="✅ Completed",L7="❌ Dropped"),"Inactive",IF(M7="Waiting for class","Waiting for class","Active")) -> Inactive | F7: {=IFERROR( INDEX(ATTENDANCE_INPUT!D:D, MATCH(1, (ATTENDANCE_INPUT!A:A=A7) * (ATTENDANCE_INPUT!W:W=MAXIFS(ATTENDANCE_INPUT!W:W, ATTENDANCE_INPUT!A:A, A7)), 0)), "")} -> Anh Ha | G7: {=IFERROR( INDEX(ATTENDANCE_INPUT!E:E, MATCH(1, (ATTENDANCE_INPUT!A:A=A7) * (ATTENDANCE_INPUT!W:W=MAXIFS(ATTENDANCE_INPUT!W:W, ATTENDANCE_INPUT!A:A, A7)), 0)), "")} -> Communication 2 | H7: {=IF(ISNA(MATCH(A7,sheet2!A:A,0)),"⏳ Chưa test",IFERROR(INDEX(LEVEL_HELPER!A:A,MATCH(INDEX(sheet2!N:N,MATCH(A7,sheet2!A:A,0)),LEVEL_HELPER!B:B,0)),"⏳ Chưa test"))} -> Beginner | I7: {=IF(ISNA(MATCH(A7,sheet2!A:A,0)),H7,IF(INDEX(sheet2!O:O,MATCH(A7,sheet2!A:A,0))>0,IFERROR(INDEX(LEVEL_HELPER!A:A,MATCH(INDEX(sheet2!O:O,MATCH(A7,sheet2!A:A,0)),LEVEL_HELPER!B:B,0)),H7),H7))} -> Intermediate 1 | J7: =IFERROR(MAXIFS(ATTENDANCE_LOG!F:F, ATTENDANCE_LOG!C:C, A7&"", ATTENDANCE_LOG!G:G, "Present"), "") -> 46106.542 | K7: =IF(J7="", "", TODAY() - J7) -> 106.45833 | L7: =IF(M7="Completed (no continuation)","✅ Completed",IF(M7="Discontinued mid-course","❌ Dropped",IF(AND(ISNUMBER(K7),K7>=30),"⚠ Check",""))) -> ✅ Completed | M7: Completed (no continuation) | N7: Learning goal achieved | P7: =IFERROR(__xludf.DUMMYFUNCTION("IFERROR(COUNTUNIQUEIFS(ATTENDANCE_LOG!B:B,ATTENDANCE_LOG!C:C,A7),0)"),2.0) -> 2 | Q7: {=IFERROR(INDEX(ATTENDANCE_LOG!A:A,MATCH(1,(ATTENDANCE_LOG!C:C=A7)*(ATTENDANCE_LOG!F:F=MAXIFS(ATTENDANCE_LOG!F:F,ATTENDANCE_LOG!C:C,A7)),0)),"")} -> EL033 | R7: {=IFERROR(INDEX(ATTENDANCE_LOG!B:B,MATCH(1,(ATTENDANCE_LOG!C:C=A7)*(ATTENDANCE_LOG!F:F=MAXIFS(ATTENDANCE_LOG!F:F,ATTENDANCE_LOG!C:C,A7)),0)),"")} -> Communication 2 | S7: =IFERROR(VLOOKUP(H7, LEVEL_HELPER!A:B, 2, 0), 0) -> 1 | T7: =IFERROR(VLOOKUP(I7, LEVEL_HELPER!A:B, 2, 0), 0) -> 5 | U7: =IF(S7="",0,IF(S7<=2,1,IF(S7<=4,2,IF(S7<=5.5,3,4)))) -> 1 | V7: =IF(T7="",0,IF(T7<=2,1,IF(T7<=4,2,IF(T7<=5.5,3,4)))) -> 3 | W7: =IF(OR(H7="", H7="Not Placement"), "Not tested yet", IF(V7<U7, "Regressed", IF(V7=U7, IF(T7>S7, "Minor Improvement", "No Progress"), IF(V7-U7=1, "Lv"&U7&"→Lv"&V7, "Lv"&U7&"→Lv"&V7&" (multi)")))) -> Lv1→Lv3 (multi) | Y7: 237172 | Z7: High workload / Can't arrange time | AA7: High workload | AC7: 247047 | AD7: =countif($A$2:$A1008,AC7) -> 0
A8: 247223 | B8: TRẦN XUÂN KHOA | C8: =IFERROR(__xludf.DUMMYFUNCTION("arrayformula(VLOOKUP(to_Text(A8),to_Text(sheet2!$A$1:M1005),13,0))"),"MOC") -> MOC | D8: =IFERROR(__xludf.DUMMYFUNCTION("arrayformula(VLOOKUP(to_Text(A8),to_Text(sheet2!$A$1:M1005),12,0))"),"DEV") -> DEV | E8: =IF(OR(L8="✅ Completed",L8="❌ Dropped"),"Inactive",IF(M8="Waiting for class","Waiting for class","Active")) -> Inactive | F8: {=IFERROR( INDEX(ATTENDANCE_INPUT!D:D, MATCH(1, (ATTENDANCE_INPUT!A:A=A8) * (ATTENDANCE_INPUT!W:W=MAXIFS(ATTENDANCE_INPUT!W:W, ATTENDANCE_INPUT!A:A, A8)), 0)), "")} -> Anh Ha | G8: {=IFERROR( INDEX(ATTENDANCE_INPUT!E:E, MATCH(1, (ATTENDANCE_INPUT!A:A=A8) * (ATTENDANCE_INPUT!W:W=MAXIFS(ATTENDANCE_INPUT!W:W, ATTENDANCE_INPUT!A:A, A8)), 0)), "")} -> Communication 2 | H8: {=IF(ISNA(MATCH(A8,sheet2!A:A,0)),"⏳ Chưa test",IFERROR(INDEX(LEVEL_HELPER!A:A,MATCH(INDEX(sheet2!N:N,MATCH(A8,sheet2!A:A,0)),LEVEL_HELPER!B:B,0)),"⏳ Chưa test"))} -> Beginner | I8: {=IF(ISNA(MATCH(A8,sheet2!A:A,0)),H8,IF(INDEX(sheet2!O:O,MATCH(A8,sheet2!A:A,0))>0,IFERROR(INDEX(LEVEL_HELPER!A:A,MATCH(INDEX(sheet2!O:O,MATCH(A8,sheet2!A:A,0)),LEVEL_HELPER!B:B,0)),H8),H8))} -> Pre-Intermediate 2 | J8: =IFERROR(MAXIFS(ATTENDANCE_LOG!F:F, ATTENDANCE_LOG!C:C, A8&"", ATTENDANCE_LOG!G:G, "Present"), "") -> 46106.542 | K8: =IF(J8="", "", TODAY() - J8) -> 106.45833 | L8: =IF(M8="Completed (no continuation)","✅ Completed",IF(M8="Discontinued mid-course","❌ Dropped",IF(AND(ISNUMBER(K8),K8>=30),"⚠ Check",""))) -> ✅ Completed | M8: Completed (no continuation) | N8: Learning goal achieved | P8: =IFERROR(__xludf.DUMMYFUNCTION("IFERROR(COUNTUNIQUEIFS(ATTENDANCE_LOG!B:B,ATTENDANCE_LOG!C:C,A8),0)"),2.0) -> 2 | Q8: {=IFERROR(INDEX(ATTENDANCE_LOG!A:A,MATCH(1,(ATTENDANCE_LOG!C:C=A8)*(ATTENDANCE_LOG!F:F=MAXIFS(ATTENDANCE_LOG!F:F,ATTENDANCE_LOG!C:C,A8)),0)),"")} -> EL033 | R8: {=IFERROR(INDEX(ATTENDANCE_LOG!B:B,MATCH(1,(ATTENDANCE_LOG!C:C=A8)*(ATTENDANCE_LOG!F:F=MAXIFS(ATTENDANCE_LOG!F:F,ATTENDANCE_LOG!C:C,A8)),0)),"")} -> Communication 2 | S8: =IFERROR(VLOOKUP(H8, LEVEL_HELPER!A:B, 2, 0), 0) -> 1 | T8: =IFERROR(VLOOKUP(I8, LEVEL_HELPER!A:B, 2, 0), 0) -> 3.5 | U8: =IF(S8="",0,IF(S8<=2,1,IF(S8<=4,2,IF(S8<=5.5,3,4)))) -> 1 | V8: =IF(T8="",0,IF(T8<=2,1,IF(T8<=4,2,IF(T8<=5.5,3,4)))) -> 2 | W8: =IF(OR(H8="", H8="Not Placement"), "Not tested yet", IF(V8<U8, "Regressed", IF(V8=U8, IF(T8>S8, "Minor Improvement", "No Progress"), IF(V8-U8=1, "Lv"&U8&"→Lv"&V8, "Lv"&U8&"→Lv"&V8&" (multi)")))) -> Lv1→Lv2 | Y8: 247040 | Z8: High workload / Can't arrange time | AA8: High workload | AC8: 227212 | AD8: =countif($A$2:$A1009,AC8) -> 0
A9: 113024 | B9: LÊ VĂN SƠN | C9: =IFERROR(__xludf.DUMMYFUNCTION("arrayformula(VLOOKUP(to_Text(A9),to_Text(sheet2!$A$1:M1005),13,0))"),"MOC") -> MOC | D9: =IFERROR(__xludf.DUMMYFUNCTION("arrayformula(VLOOKUP(to_Text(A9),to_Text(sheet2!$A$1:M1005),12,0))"),"DEV") -> DEV | E9: =IF(OR(L9="✅ Completed",L9="❌ Dropped"),"Inactive",IF(M9="Waiting for class","Waiting for class","Active")) -> Waiting for class | F9: {=IFERROR( INDEX(ATTENDANCE_INPUT!D:D, MATCH(1, (ATTENDANCE_INPUT!A:A=A9) * (ATTENDANCE_INPUT!W:W=MAXIFS(ATTENDANCE_INPUT!W:W, ATTENDANCE_INPUT!A:A, A9)), 0)), "")} -> Anh Ha | G9: {=IFERROR( INDEX(ATTENDANCE_INPUT!E:E, MATCH(1, (ATTENDANCE_INPUT!A:A=A9) * (ATTENDANCE_INPUT!W:W=MAXIFS(ATTENDANCE_INPUT!W:W, ATTENDANCE_INPUT!A:A, A9)), 0)), "")} -> Communication 2 | H9: {=IF(ISNA(MATCH(A9,sheet2!A:A,0)),"⏳ Chưa test",IFERROR(INDEX(LEVEL_HELPER!A:A,MATCH(INDEX(sheet2!N:N,MATCH(A9,sheet2!A:A,0)),LEVEL_HELPER!B:B,0)),"⏳ Chưa test"))} -> Beginner | I9: {=IF(ISNA(MATCH(A9,sheet2!A:A,0)),H9,IF(INDEX(sheet2!O:O,MATCH(A9,sheet2!A:A,0))>0,IFERROR(INDEX(LEVEL_HELPER!A:A,MATCH(INDEX(sheet2!O:O,MATCH(A9,sheet2!A:A,0)),LEVEL_HELPER!B:B,0)),H9),H9))} -> Pre-Intermediate 1 | J9: =IFERROR(MAXIFS(ATTENDANCE_LOG!F:F, ATTENDANCE_LOG!C:C, A9&"", ATTENDANCE_LOG!G:G, "Present"), "") -> 46106.542 | K9: =IF(J9="", "", TODAY() - J9) -> 106.45833 | L9: =IF(M9="Completed (no continuation)","✅ Completed",IF(M9="Discontinued mid-course","❌ Dropped",IF(AND(ISNUMBER(K9),K9>=30),"⚠ Check",""))) -> ⚠ Check | M9: Waiting for class | O9: Chờ ghép lớp com 3 | P9: =IFERROR(__xludf.DUMMYFUNCTION("IFERROR(COUNTUNIQUEIFS(ATTENDANCE_LOG!B:B,ATTENDANCE_LOG!C:C,A9),0)"),2.0) -> 2 | Q9: {=IFERROR(INDEX(ATTENDANCE_LOG!A:A,MATCH(1,(ATTENDANCE_LOG!C:C=A9)*(ATTENDANCE_LOG!F:F=MAXIFS(ATTENDANCE_LOG!F:F,ATTENDANCE_LOG!C:C,A9)),0)),"")} -> EL033 | R9: {=IFERROR(INDEX(ATTENDANCE_LOG!B:B,MATCH(1,(ATTENDANCE_LOG!C:C=A9)*(ATTENDANCE_LOG!F:F=MAXIFS(ATTENDANCE_LOG!F:F,ATTENDANCE_LOG!C:C,A9)),0)),"")} -> Communication 2 | S9: =IFERROR(VLOOKUP(H9, LEVEL_HELPER!A:B, 2, 0), 0) -> 1 | T9: =IFERROR(VLOOKUP(I9, LEVEL_HELPER!A:B, 2, 0), 0) -> 3 | U9: =IF(S9="",0,IF(S9<=2,1,IF(S9<=4,2,IF(S9<=5.5,3,4)))) -> 1 | V9: =IF(T9="",0,IF(T9<=2,1,IF(T9<=4,2,IF(T9<=5.5,3,4)))) -> 2 | W9: =IF(OR(H9="", H9="Not Placement"), "Not tested yet", IF(V9<U9, "Regressed", IF(V9=U9, IF(T9>S9, "Minor Improvement", "No Progress"), IF(V9-U9=1, "Lv"&U9&"→Lv"&V9, "Lv"&U9&"→Lv"&V9&" (multi)")))) -> Lv1→Lv2 | Y9: 237167 | Z9: Left | AA9: Resgined | AC9: 247029 | AD9: =countif($A$2:$A1010,AC9) -> 0
A10: 247378 | B10: NGUYỄN BẢO ĐẠT | C10: =IFERROR(__xludf.DUMMYFUNCTION("arrayformula(VLOOKUP(to_Text(A10),to_Text(sheet2!$A$1:M1005),13,0))"),"MOC") -> MOC | D10: =IFERROR(__xludf.DUMMYFUNCTION("arrayformula(VLOOKUP(to_Text(A10),to_Text(sheet2!$A$1:M1005),12,0))"),"QC") -> QC | E10: =IF(OR(L10="✅ Completed",L10="❌ Dropped"),"Inactive",IF(M10="Waiting for class","Waiting for class","Active")) -> Inactive | F10: {=IFERROR( INDEX(ATTENDANCE_INPUT!D:D, MATCH(1, (ATTENDANCE_INPUT!A:A=A10) * (ATTENDANCE_INPUT!W:W=MAXIFS(ATTENDANCE_INPUT!W:W, ATTENDANCE_INPUT!A:A, A10)), 0)), "")} -> Anh To | G10: {=IFERROR( INDEX(ATTENDANCE_INPUT!E:E, MATCH(1, (ATTENDANCE_INPUT!A:A=A10) * (ATTENDANCE_INPUT!W:W=MAXIFS(ATTENDANCE_INPUT!W:W, ATTENDANCE_INPUT!A:A, A10)), 0)), "")} -> Communication 2 | H10: {=IF(ISNA(MATCH(A10,sheet2!A:A,0)),"⏳ Chưa test",IFERROR(INDEX(LEVEL_HELPER!A:A,MATCH(INDEX(sheet2!N:N,MATCH(A10,sheet2!A:A,0)),LEVEL_HELPER!B:B,0)),"⏳ Chưa test"))} -> Beginner | I10: {=IF(ISNA(MATCH(A10,sheet2!A:A,0)),H10,IF(INDEX(sheet2!O:O,MATCH(A10,sheet2!A:A,0))>0,IFERROR(INDEX(LEVEL_HELPER!A:A,MATCH(INDEX(sheet2!O:O,MATCH(A10,sheet2!A:A,0)),LEVEL_HELPER!B:B,0)),H10),H10))} -> Intermediate 1 | J10: =IFERROR(MAXIFS(ATTENDANCE_LOG!F:F, ATTENDANCE_LOG!C:C, A10&"", ATTENDANCE_LOG!G:G, "Present"), "") -> 46136.417 | K10: =IF(J10="", "", TODAY() - J10) -> 76.583333 | L10: =IF(M10="Completed (no continuation)","✅ Completed",IF(M10="Discontinued mid-course","❌ Dropped",IF(AND(ISNUMBER(K10),K10>=30),"⚠ Check",""))) -> ✅ Completed | M10: Completed (no continuation) | N10: High workload | O10: Chờ ghép lớp com 3 tháng 7/8 | P10: =IFERROR(__xludf.DUMMYFUNCTION("IFERROR(COUNTUNIQUEIFS(ATTENDANCE_LOG!B:B,ATTENDANCE_LOG!C:C,A10),0)"),2.0) -> 2 | Q10: {=IFERROR(INDEX(ATTENDANCE_LOG!A:A,MATCH(1,(ATTENDANCE_LOG!C:C=A10)*(ATTENDANCE_LOG!F:F=MAXIFS(ATTENDANCE_LOG!F:F,ATTENDANCE_LOG!C:C,A10)),0)),"")} -> EL025 | R10: {=IFERROR(INDEX(ATTENDANCE_LOG!B:B,MATCH(1,(ATTENDANCE_LOG!C:C=A10)*(ATTENDANCE_LOG!F:F=MAXIFS(ATTENDANCE_LOG!F:F,ATTENDANCE_LOG!C:C,A10)),0)),"")} -> Communication 2 | S10: =IFERROR(VLOOKUP(H10, LEVEL_HELPER!A:B, 2, 0), 0) -> 1 | T10: =IFERROR(VLOOKUP(I10, LEVEL_HELPER!A:B, 2, 0), 0) -> 5 | U10: =IF(S10="",0,IF(S10<=2,1,IF(S10<=4,2,IF(S10<=5.5,3,4)))) -> 1 | V10: =IF(T10="",0,IF(T10<=2,1,IF(T10<=4,2,IF(T10<=5.5,3,4)))) -> 3 | W10: =IF(OR(H10="", H10="Not Placement"), "Not tested yet", IF(V10<U10, "Regressed", IF(V10=U10, IF(T10>S10, "Minor Improvement", "No Progress"), IF(V10-U10=1, "Lv"&U10&"→Lv"&V10, "Lv"&U10&"→Lv"&V10&" (multi)")))) -> Lv1→Lv3 (multi) | Y10: 247140 | Z10: Ungroup team | AA10: Team restructuring | AC10: 247099 | AD10: =countif($A$2:$A1011,AC10) -> 0
A11: 203765 | B11: ĐỖ GIA KHÁNH | C11: =IFERROR(__xludf.DUMMYFUNCTION("arrayformula(VLOOKUP(to_Text(A11),to_Text(sheet2!$A$1:M1005),13,0))"),"MOC") -> MOC | D11: =IFERROR(__xludf.DUMMYFUNCTION("arrayformula(VLOOKUP(to_Text(A11),to_Text(sheet2!$A$1:M1005),12,0))"),"DEV") -> DEV | E11: =IF(OR(L11="✅ Completed",L11="❌ Dropped"),"Inactive",IF(M11="Waiting for class","Waiting for class","Active")) -> Waiting for class | F11: {=IFERROR( INDEX(ATTENDANCE_INPUT!D:D, MATCH(1, (ATTENDANCE_INPUT!A:A=A11) * (ATTENDANCE_INPUT!W:W=MAXIFS(ATTENDANCE_INPUT!W:W, ATTENDANCE_INPUT!A:A, A11)), 0)), "")} -> Anh To | G11: {=IFERROR( INDEX(ATTENDANCE_INPUT!E:E, MATCH(1, (ATTENDANCE_INPUT!A:A=A11) * (ATTENDANCE_INPUT!W:W=MAXIFS(ATTENDANCE_INPUT!W:W, ATTENDANCE_INPUT!A:A, A11)), 0)), "")} -> Communication 2 | H11: {=IF(ISNA(MATCH(A11,sheet2!A:A,0)),"⏳ Chưa test",IFERROR(INDEX(LEVEL_HELPER!A:A,MATCH(INDEX(sheet2!N:N,MATCH(A11,sheet2!A:A,0)),LEVEL_HELPER!B:B,0)),"⏳ Chưa test"))} -> Beginner | I11: {=IF(ISNA(MATCH(A11,sheet2!A:A,0)),H11,IF(INDEX(sheet2!O:O,MATCH(A11,sheet2!A:A,0))>0,IFERROR(INDEX(LEVEL_HELPER!A:A,MATCH(INDEX(sheet2!O:O,MATCH(A11,sheet2!A:A,0)),LEVEL_HELPER!B:B,0)),H11),H11))} -> Pre-Intermediate 2 | J11: =IFERROR(MAXIFS(ATTENDANCE_LOG!F:F, ATTENDANCE_LOG!C:C, A11&"", ATTENDANCE_LOG!G:G, "Present"), "") -> 46136.417 | K11: =IF(J11="", "", TODAY() - J11) -> 76.583333 | L11: =IF(M11="Completed (no continuation)","✅ Completed",IF(M11="Discontinued mid-course","❌ Dropped",IF(AND(ISNUMBER(K11),K11>=30),"⚠ Check",""))) -> ⚠ Check | M11: Waiting for class | O11: Chờ ghép lớp com 3 tháng 7/8 | P11: =IFERROR(__xludf.DUMMYFUNCTION("IFERROR(COUNTUNIQUEIFS(ATTENDANCE_LOG!B:B,ATTENDANCE_LOG!C:C,A11),0)"),2.0) -> 2 | Q11: {=IFERROR(INDEX(ATTENDANCE_LOG!A:A,MATCH(1,(ATTENDANCE_LOG!C:C=A11)*(ATTENDANCE_LOG!F:F=MAXIFS(ATTENDANCE_LOG!F:F,ATTENDANCE_LOG!C:C,A11)),0)),"")} -> EL025 | R11: {=IFERROR(INDEX(ATTENDANCE_LOG!B:B,MATCH(1,(ATTENDANCE_LOG!C:C=A11)*(ATTENDANCE_LOG!F:F=MAXIFS(ATTENDANCE_LOG!F:F,ATTENDANCE_LOG!C:C,A11)),0)),"")} -> Communication 2 | S11: =IFERROR(VLOOKUP(H11, LEVEL_HELPER!A:B, 2, 0), 0) -> 1 | T11: =IFERROR(VLOOKUP(I11, LEVEL_HELPER!A:B, 2, 0), 0) -> 3.5 | U11: =IF(S11="",0,IF(S11<=2,1,IF(S11<=4,2,IF(S11<=5.5,3,4)))) -> 1 | V11: =IF(T11="",0,IF(T11<=2,1,IF(T11<=4,2,IF(T11<=5.5,3,4)))) -> 2 | W11: =IF(OR(H11="", H11="Not Placement"), "Not tested yet", IF(V11<U11, "Regressed", IF(V11=U11, IF(T11>S11, "Minor Improvement", "No Progress"), IF(V11-U11=1, "Lv"&U11&"→Lv"&V11, "Lv"&U11&"→Lv"&V11&" (multi)")))) -> Lv1→Lv2 | Y11: 247309 | Z11: High workload / Can't arrange time | AA11: High workload
A12: 247225 | B12: LÊ PHƯỚC THIỆN | C12: =IFERROR(__xludf.DUMMYFUNCTION("arrayformula(VLOOKUP(to_Text(A12),to_Text(sheet2!$A$1:M1005),13,0))"),"MOC") -> MOC | D12: =IFERROR(__xludf.DUMMYFUNCTION("arrayformula(VLOOKUP(to_Text(A12),to_Text(sheet2!$A$1:M1005),12,0))"),"DEV") -> DEV | E12: =IF(OR(L12="✅ Completed",L12="❌ Dropped"),"Inactive",IF(M12="Waiting for class","Waiting for class","Active")) -> Waiting for class | F12: {=IFERROR( INDEX(ATTENDANCE_INPUT!D:D, MATCH(1, (ATTENDANCE_INPUT!A:A=A12) * (ATTENDANCE_INPUT!W:W=MAXIFS(ATTENDANCE_INPUT!W:W, ATTENDANCE_INPUT!A:A, A12)), 0)), "")} -> Anh To | G12: {=IFERROR( INDEX(ATTENDANCE_INPUT!E:E, MATCH(1, (ATTENDANCE_INPUT!A:A=A12) * (ATTENDANCE_INPUT!W:W=MAXIFS(ATTENDANCE_INPUT!W:W, ATTENDANCE_INPUT!A:A, A12)), 0)), "")} -> Communication 2 | H12: {=IF(ISNA(MATCH(A12,sheet2!A:A,0)),"⏳ Chưa test",IFERROR(INDEX(LEVEL_HELPER!A:A,MATCH(INDEX(sheet2!N:N,MATCH(A12,sheet2!A:A,0)),LEVEL_HELPER!B:B,0)),"⏳ Chưa test"))} -> Beginner | I12: {=IF(ISNA(MATCH(A12,sheet2!A:A,0)),H12,IF(INDEX(sheet2!O:O,MATCH(A12,sheet2!A:A,0))>0,IFERROR(INDEX(LEVEL_HELPER!A:A,MATCH(INDEX(sheet2!O:O,MATCH(A12,sheet2!A:A,0)),LEVEL_HELPER!B:B,0)),H12),H12))} -> Pre-Intermediate 1 | J12: =IFERROR(MAXIFS(ATTENDANCE_LOG!F:F, ATTENDANCE_LOG!C:C, A12&"", ATTENDANCE_LOG!G:G, "Present"), "") -> 46136.417 | K12: =IF(J12="", "", TODAY() - J12) -> 76.583333 | L12: =IF(M12="Completed (no continuation)","✅ Completed",IF(M12="Discontinued mid-course","❌ Dropped",IF(AND(ISNUMBER(K12),K12>=30),"⚠ Check",""))) -> ⚠ Check | M12: Waiting for class | O12: Chờ ghép lớp com 3 tháng 7/8 | P12: =IFERROR(__xludf.DUMMYFUNCTION("IFERROR(COUNTUNIQUEIFS(ATTENDANCE_LOG!B:B,ATTENDANCE_LOG!C:C,A12),0)"),2.0) -> 2 | Q12: {=IFERROR(INDEX(ATTENDANCE_LOG!A:A,MATCH(1,(ATTENDANCE_LOG!C:C=A12)*(ATTENDANCE_LOG!F:F=MAXIFS(ATTENDANCE_LOG!F:F,ATTENDANCE_LOG!C:C,A12)),0)),"")} -> EL025 | R12: {=IFERROR(INDEX(ATTENDANCE_LOG!B:B,MATCH(1,(ATTENDANCE_LOG!C:C=A12)*(ATTENDANCE_LOG!F:F=MAXIFS(ATTENDANCE_LOG!F:F,ATTENDANCE_LOG!C:C,A12)),0)),"")} -> Communication 2 | S12: =IFERROR(VLOOKUP(H12, LEVEL_HELPER!A:B, 2, 0), 0) -> 1 | T12: =IFERROR(VLOOKUP(I12, LEVEL_HELPER!A:B, 2, 0), 0) -> 3 | U12: =IF(S12="",0,IF(S12<=2,1,IF(S12<=4,2,IF(S12<=5.5,3,4)))) -> 1 | V12: =IF(T12="",0,IF(T12<=2,1,IF(T12<=4,2,IF(T12<=5.5,3,4)))) -> 2 | W12: =IF(OR(H12="", H12="Not Placement"), "Not tested yet", IF(V12<U12, "Regressed", IF(V12=U12, IF(T12>S12, "Minor Improvement", "No Progress"), IF(V12-U12=1, "Lv"&U12&"→Lv"&V12, "Lv"&U12&"→Lv"&V12&" (multi)")))) -> Lv1→Lv2 | Y12: 247139 | Z12: Ungroup team | AA12: Team restructuring
A13: 213947 | B13: NGUYỄN NGỌC PHƯƠNG NHI | C13: =IFERROR(__xludf.DUMMYFUNCTION("arrayformula(VLOOKUP(to_Text(A13),to_Text(sheet2!$A$1:M1005),13,0))"),"MOC") -> MOC | D13: =IFERROR(__xludf.DUMMYFUNCTION("arrayformula(VLOOKUP(to_Text(A13),to_Text(sheet2!$A$1:M1005),12,0))"),"QC") -> QC | E13: =IF(OR(L13="✅ Completed",L13="❌ Dropped"),"Inactive",IF(M13="Waiting for class","Waiting for class","Active")) -> Waiting for class | F13: {=IFERROR( INDEX(ATTENDANCE_INPUT!D:D, MATCH(1, (ATTENDANCE_INPUT!A:A=A13) * (ATTENDANCE_INPUT!W:W=MAXIFS(ATTENDANCE_INPUT!W:W, ATTENDANCE_INPUT!A:A, A13)), 0)), "")} -> Anh To | G13: {=IFERROR( INDEX(ATTENDANCE_INPUT!E:E, MATCH(1, (ATTENDANCE_INPUT!A:A=A13) * (ATTENDANCE_INPUT!W:W=MAXIFS(ATTENDANCE_INPUT!W:W, ATTENDANCE_INPUT!A:A, A13)), 0)), "")} -> Communication 2 | H13: {=IF(ISNA(MATCH(A13,sheet2!A:A,0)),"⏳ Chưa test",IFERROR(INDEX(LEVEL_HELPER!A:A,MATCH(INDEX(sheet2!N:N,MATCH(A13,sheet2!A:A,0)),LEVEL_HELPER!B:B,0)),"⏳ Chưa test"))} -> Beginner | I13: {=IF(ISNA(MATCH(A13,sheet2!A:A,0)),H13,IF(INDEX(sheet2!O:O,MATCH(A13,sheet2!A:A,0))>0,IFERROR(INDEX(LEVEL_HELPER!A:A,MATCH(INDEX(sheet2!O:O,MATCH(A13,sheet2!A:A,0)),LEVEL_HELPER!B:B,0)),H13),H13))} -> Pre-Intermediate 1 | J13: =IFERROR(MAXIFS(ATTENDANCE_LOG!F:F, ATTENDANCE_LOG!C:C, A13&"", ATTENDANCE_LOG!G:G, "Present"), "") -> 46136.417 | K13: =IF(J13="", "", TODAY() - J13) -> 76.583333 | L13: =IF(M13="Completed (no continuation)","✅ Completed",IF(M13="Discontinued mid-course","❌ Dropped",IF(AND(ISNUMBER(K13),K13>=30),"⚠ Check",""))) -> ⚠ Check | M13: Waiting for class | O13: Chờ ghép lớp com 3 tháng 7/8 | P13: =IFERROR(__xludf.DUMMYFUNCTION("IFERROR(COUNTUNIQUEIFS(ATTENDANCE_LOG!B:B,ATTENDANCE_LOG!C:C,A13),0)"),2.0) -> 2 | Q13: {=IFERROR(INDEX(ATTENDANCE_LOG!A:A,MATCH(1,(ATTENDANCE_LOG!C:C=A13)*(ATTENDANCE_LOG!F:F=MAXIFS(ATTENDANCE_LOG!F:F,ATTENDANCE_LOG!C:C,A13)),0)),"")} -> EL025 | R13: {=IFERROR(INDEX(ATTENDANCE_LOG!B:B,MATCH(1,(ATTENDANCE_LOG!C:C=A13)*(ATTENDANCE_LOG!F:F=MAXIFS(ATTENDANCE_LOG!F:F,ATTENDANCE_LOG!C:C,A13)),0)),"")} -> Communication 2 | S13: =IFERROR(VLOOKUP(H13, LEVEL_HELPER!A:B, 2, 0), 0) -> 1 | T13: =IFERROR(VLOOKUP(I13, LEVEL_HELPER!A:B, 2, 0), 0) -> 3 | U13: =IF(S13="",0,IF(S13<=2,1,IF(S13<=4,2,IF(S13<=5.5,3,4)))) -> 1 | V13: =IF(T13="",0,IF(T13<=2,1,IF(T13<=4,2,IF(T13<=5.5,3,4)))) -> 2 | W13: =IF(OR(H13="", H13="Not Placement"), "Not tested yet", IF(V13<U13, "Regressed", IF(V13=U13, IF(T13>S13, "Minor Improvement", "No Progress"), IF(V13-U13=1, "Lv"&U13&"→Lv"&V13, "Lv"&U13&"→Lv"&V13&" (multi)")))) -> Lv1→Lv2 | Y13: 247135 | Z13: Ungroup team | AA13: Team restructuring
A14: 213876 | B14: TÔ DIỆP THIÊN ANH | C14: =IFERROR(__xludf.DUMMYFUNCTION("arrayformula(VLOOKUP(to_Text(A14),to_Text(sheet2!$A$1:M1005),13,0))"),"MOC") -> MOC | D14: =IFERROR(__xludf.DUMMYFUNCTION("arrayformula(VLOOKUP(to_Text(A14),to_Text(sheet2!$A$1:M1005),12,0))"),"DEV") -> DEV | E14: =IF(OR(L14="✅ Completed",L14="❌ Dropped"),"Inactive",IF(M14="Waiting for class","Waiting for class","Active")) -> Waiting for class | F14: {=IFERROR( INDEX(ATTENDANCE_INPUT!D:D, MATCH(1, (ATTENDANCE_INPUT!A:A=A14) * (ATTENDANCE_INPUT!W:W=MAXIFS(ATTENDANCE_INPUT!W:W, ATTENDANCE_INPUT!A:A, A14)), 0)), "")} -> Anh To | G14: {=IFERROR( INDEX(ATTENDANCE_INPUT!E:E, MATCH(1, (ATTENDANCE_INPUT!A:A=A14) * (ATTENDANCE_INPUT!W:W=MAXIFS(ATTENDANCE_INPUT!W:W, ATTENDANCE_INPUT!A:A, A14)), 0)), "")} -> Communication 2 | H14: {=IF(ISNA(MATCH(A14,sheet2!A:A,0)),"⏳ Chưa test",IFERROR(INDEX(LEVEL_HELPER!A:A,MATCH(INDEX(sheet2!N:N,MATCH(A14,sheet2!A:A,0)),LEVEL_HELPER!B:B,0)),"⏳ Chưa test"))} -> Beginner | I14: {=IF(ISNA(MATCH(A14,sheet2!A:A,0)),H14,IF(INDEX(sheet2!O:O,MATCH(A14,sheet2!A:A,0))>0,IFERROR(INDEX(LEVEL_HELPER!A:A,MATCH(INDEX(sheet2!O:O,MATCH(A14,sheet2!A:A,0)),LEVEL_HELPER!B:B,0)),H14),H14))} -> Pre-Intermediate 2 | J14: =IFERROR(MAXIFS(ATTENDANCE_LOG!F:F, ATTENDANCE_LOG!C:C, A14&"", ATTENDANCE_LOG!G:G, "Present"), "") -> 46136.417 | K14: =IF(J14="", "", TODAY() - J14) -> 76.583333 | L14: =IF(M14="Completed (no continuation)","✅ Completed",IF(M14="Discontinued mid-course","❌ Dropped",IF(AND(ISNUMBER(K14),K14>=30),"⚠ Check",""))) -> ⚠ Check | M14: Waiting for class | O14: Chờ ghép lớp com 3 tháng 7/8 | P14: =IFERROR(__xludf.DUMMYFUNCTION("IFERROR(COUNTUNIQUEIFS(ATTENDANCE_LOG!B:B,ATTENDANCE_LOG!C:C,A14),0)"),2.0) -> 2 | Q14: {=IFERROR(INDEX(ATTENDANCE_LOG!A:A,MATCH(1,(ATTENDANCE_LOG!C:C=A14)*(ATTENDANCE_LOG!F:F=MAXIFS(ATTENDANCE_LOG!F:F,ATTENDANCE_LOG!C:C,A14)),0)),"")} -> EL025 | R14: {=IFERROR(INDEX(ATTENDANCE_LOG!B:B,MATCH(1,(ATTENDANCE_LOG!C:C=A14)*(ATTENDANCE_LOG!F:F=MAXIFS(ATTENDANCE_LOG!F:F,ATTENDANCE_LOG!C:C,A14)),0)),"")} -> Communication 2 | S14: =IFERROR(VLOOKUP(H14, LEVEL_HELPER!A:B, 2, 0), 0) -> 1 | T14: =IFERROR(VLOOKUP(I14, LEVEL_HELPER!A:B, 2, 0), 0) -> 3.5 | U14: =IF(S14="",0,IF(S14<=2,1,IF(S14<=4,2,IF(S14<=5.5,3,4)))) -> 1 | V14: =IF(T14="",0,IF(T14<=2,1,IF(T14<=4,2,IF(T14<=5.5,3,4)))) -> 2 | W14: =IF(OR(H14="", H14="Not Placement"), "Not tested yet", IF(V14<U14, "Regressed", IF(V14=U14, IF(T14>S14, "Minor Improvement", "No Progress"), IF(V14-U14=1, "Lv"&U14&"→Lv"&V14, "Lv"&U14&"→Lv"&V14&" (multi)")))) -> Lv1→Lv2 | Y14: 247213 | Z14: Ungroup team | AA14: Team restructuring
A15: 247245 | B15: THÁI NHẬT TÂN | C15: =IFERROR(__xludf.DUMMYFUNCTION("arrayformula(VLOOKUP(to_Text(A15),to_Text(sheet2!$A$1:M1005),13,0))"),"LBU") -> LBU | D15: =IFERROR(__xludf.DUMMYFUNCTION("arrayformula(VLOOKUP(to_Text(A15),to_Text(sheet2!$A$1:M1005),12,0))"),"DEV") -> DEV | E15: =IF(OR(L15="✅ Completed",L15="❌ Dropped"),"Inactive",IF(M15="Waiting for class","Waiting for class","Active")) -> Inactive | F15: {=IFERROR( INDEX(ATTENDANCE_INPUT!D:D, MATCH(1, (ATTENDANCE_INPUT!A:A=A15) * (ATTENDANCE_INPUT!W:W=MAXIFS(ATTENDANCE_INPUT!W:W, ATTENDANCE_INPUT!A:A, A15)), 0)), "")} -> Anh To | G15: {=IFERROR( INDEX(ATTENDANCE_INPUT!E:E, MATCH(1, (ATTENDANCE_INPUT!A:A=A15) * (ATTENDANCE_INPUT!W:W=MAXIFS(ATTENDANCE_INPUT!W:W, ATTENDANCE_INPUT!A:A, A15)), 0)), "")} -> Communication 1 | H15: {=IF(ISNA(MATCH(A15,sheet2!A:A,0)),"⏳ Chưa test",IFERROR(INDEX(LEVEL_HELPER!A:A,MATCH(INDEX(sheet2!N:N,MATCH(A15,sheet2!A:A,0)),LEVEL_HELPER!B:B,0)),"⏳ Chưa test"))} -> Beginner | I15: {=IF(ISNA(MATCH(A15,sheet2!A:A,0)),H15,IF(INDEX(sheet2!O:O,MATCH(A15,sheet2!A:A,0))>0,IFERROR(INDEX(LEVEL_HELPER!A:A,MATCH(INDEX(sheet2!O:O,MATCH(A15,sheet2!A:A,0)),LEVEL_HELPER!B:B,0)),H15),H15))} -> Pre-Intermediate 1 | J15: =IFERROR(MAXIFS(ATTENDANCE_LOG!F:F, ATTENDANCE_LOG!C:C, A15&"", ATTENDANCE_LOG!G:G, "Present"), "") -> 45894.542 | K15: =IF(J15="", "", TODAY() - J15) -> 318.45833 | L15: =IF(M15="Completed (no continuation)","✅ Completed",IF(M15="Discontinued mid-course","❌ Dropped",IF(AND(ISNUMBER(K15),K15>=30),"⚠ Check",""))) -> ❌ Dropped | M15: Discontinued mid-course | N15: High workload | P15: =IFERROR(__xludf.DUMMYFUNCTION("IFERROR(COUNTUNIQUEIFS(ATTENDANCE_LOG!B:B,ATTENDANCE_LOG!C:C,A15),0)"),1.0) -> 1 | Q15: {=IFERROR(INDEX(ATTENDANCE_LOG!A:A,MATCH(1,(ATTENDANCE_LOG!C:C=A15)*(ATTENDANCE_LOG!F:F=MAXIFS(ATTENDANCE_LOG!F:F,ATTENDANCE_LOG!C:C,A15)),0)),"")} -> EL025 | R15: {=IFERROR(INDEX(ATTENDANCE_LOG!B:B,MATCH(1,(ATTENDANCE_LOG!C:C=A15)*(ATTENDANCE_LOG!F:F=MAXIFS(ATTENDANCE_LOG!F:F,ATTENDANCE_LOG!C:C,A15)),0)),"")} -> Communication 1 | S15: =IFERROR(VLOOKUP(H15, LEVEL_HELPER!A:B, 2, 0), 0) -> 1 | T15: =IFERROR(VLOOKUP(I15, LEVEL_HELPER!A:B, 2, 0), 0) -> 3 | U15: =IF(S15="",0,IF(S15<=2,1,IF(S15<=4,2,IF(S15<=5.5,3,4)))) -> 1 | V15: =IF(T15="",0,IF(T15<=2,1,IF(T15<=4,2,IF(T15<=5.5,3,4)))) -> 2 | W15: =IF(OR(H15="", H15="Not Placement"), "Not tested yet", IF(V15<U15, "Regressed", IF(V15=U15, IF(T15>S15, "Minor Improvement", "No Progress"), IF(V15-U15=1, "Lv"&U15&"→Lv"&V15, "Lv"&U15&"→Lv"&V15&" (multi)")))) -> Lv1→Lv2 | Y15: 247142 | Z15: Ungroup team | AA15: Team restructuring
A16: 237050 | B16: TRẦN THỊ THANH NGA | C16: =IFERROR(__xludf.DUMMYFUNCTION("arrayformula(VLOOKUP(to_Text(A16),to_Text(sheet2!$A$1:M1005),13,0))"),"POC") -> POC | D16: =IFERROR(__xludf.DUMMYFUNCTION("arrayformula(VLOOKUP(to_Text(A16),to_Text(sheet2!$A$1:M1005),12,0))"),"QC") -> QC | E16: =IF(OR(L16="✅ Completed",L16="❌ Dropped"),"Inactive",IF(M16="Waiting for class","Waiting for class","Active")) -> Active | F16: {=IFERROR( INDEX(ATTENDANCE_INPUT!D:D, MATCH(1, (ATTENDANCE_INPUT!A:A=A16) * (ATTENDANCE_INPUT!W:W=MAXIFS(ATTENDANCE_INPUT!W:W, ATTENDANCE_INPUT!A:A, A16)), 0)), "")} -> Anh Vu | G16: {=IFERROR( INDEX(ATTENDANCE_INPUT!E:E, MATCH(1, (ATTENDANCE_INPUT!A:A=A16) * (ATTENDANCE_INPUT!W:W=MAXIFS(ATTENDANCE_INPUT!W:W, ATTENDANCE_INPUT!A:A, A16)), 0)), "")} -> Business English | H16: {=IF(ISNA(MATCH(A16,sheet2!A:A,0)),"⏳ Chưa test",IFERROR(INDEX(LEVEL_HELPER!A:A,MATCH(INDEX(sheet2!N:N,MATCH(A16,sheet2!A:A,0)),LEVEL_HELPER!B:B,0)),"⏳ Chưa test"))} -> Intermediate | I16: {=IF(ISNA(MATCH(A16,sheet2!A:A,0)),H16,IF(INDEX(sheet2!O:O,MATCH(A16,sheet2!A:A,0))>0,IFERROR(INDEX(LEVEL_HELPER!A:A,MATCH(INDEX(sheet2!O:O,MATCH(A16,sheet2!A:A,0)),LEVEL_HELPER!B:B,0)),H16),H16))} -> Intermediate 2 | J16: =IFERROR(MAXIFS(ATTENDANCE_LOG!F:F, ATTENDANCE_LOG!C:C, A16&"", ATTENDANCE_LOG!G:G, "Present"), "") -> 46211.583 | K16: =IF(J16="", "", TODAY() - J16) -> 1.4166667 | L16: =IF(M16="Completed (no continuation)","✅ Completed",IF(M16="Discontinued mid-course","❌ Dropped",IF(AND(ISNUMBER(K16),K16>=30),"⚠ Check",""))) | P16: =IFERROR(__xludf.DUMMYFUNCTION("IFERROR(COUNTUNIQUEIFS(ATTENDANCE_LOG!B:B,ATTENDANCE_LOG!C:C,A16),0)"),3.0) -> 3 | Q16: {=IFERROR(INDEX(ATTENDANCE_LOG!A:A,MATCH(1,(ATTENDANCE_LOG!C:C=A16)*(ATTENDANCE_LOG!F:F=MAXIFS(ATTENDANCE_LOG!F:F,ATTENDANCE_LOG!C:C,A16)),0)),"")} -> EL001 | R16: {=IFERROR(INDEX(ATTENDANCE_LOG!B:B,MATCH(1,(ATTENDANCE_LOG!C:C=A16)*(ATTENDANCE_LOG!F:F=MAXIFS(ATTENDANCE_LOG!F:F,ATTENDANCE_LOG!C:C,A16)),0)),"")} -> Business English | S16: =IFERROR(VLOOKUP(H16, LEVEL_HELPER!A:B, 2, 0), 0) -> 4.5 | T16: =IFERROR(VLOOKUP(I16, LEVEL_HELPER!A:B, 2, 0), 0) -> 5.5 | U16: =IF(S16="",0,IF(S16<=2,1,IF(S16<=4,2,IF(S16<=5.5,3,4)))) -> 3 | V16: =IF(T16="",0,IF(T16<=2,1,IF(T16<=4,2,IF(T16<=5.5,3,4)))) -> 3 | W16: =IF(OR(H16="", H16="Not Placement"), "Not tested yet", IF(V16<U16, "Regressed", IF(V16=U16, IF(T16>S16, "Minor Improvement", "No Progress"), IF(V16-U16=1, "Lv"&U16&"→Lv"&V16, "Lv"&U16&"→Lv"&V16&" (multi)")))) -> Minor Improvement | Y16: 247174 | Z16: Ungroup team | AA16: Team restructuring
A17: 227148 | B17: TRẦN THỊ THÙY DUNG | C17: =IFERROR(__xludf.DUMMYFUNCTION("arrayformula(VLOOKUP(to_Text(A17),to_Text(sheet2!$A$1:M1005),13,0))"),"POC") -> POC | D17: =IFERROR(__xludf.DUMMYFUNCTION("arrayformula(VLOOKUP(to_Text(A17),to_Text(sheet2!$A$1:M1005),12,0))"),"QC") -> QC | E17: =IF(OR(L17="✅ Completed",L17="❌ Dropped"),"Inactive",IF(M17="Waiting for class","Waiting for class","Active")) -> Active | F17: {=IFERROR( INDEX(ATTENDANCE_INPUT!D:D, MATCH(1, (ATTENDANCE_INPUT!A:A=A17) * (ATTENDANCE_INPUT!W:W=MAXIFS(ATTENDANCE_INPUT!W:W, ATTENDANCE_INPUT!A:A, A17)), 0)), "")} -> Anh Vu | G17: {=IFERROR( INDEX(ATTENDANCE_INPUT!E:E, MATCH(1, (ATTENDANCE_INPUT!A:A=A17) * (ATTENDANCE_INPUT!W:W=MAXIFS(ATTENDANCE_INPUT!W:W, ATTENDANCE_INPUT!A:A, A17)), 0)), "")} -> Business English | H17: {=IF(ISNA(MATCH(A17,sheet2!A:A,0)),"⏳ Chưa test",IFERROR(INDEX(LEVEL_HELPER!A:A,MATCH(INDEX(sheet2!N:N,MATCH(A17,sheet2!A:A,0)),LEVEL_HELPER!B:B,0)),"⏳ Chưa test"))} -> Beginner | I17: {=IF(ISNA(MATCH(A17,sheet2!A:A,0)),H17,IF(INDEX(sheet2!O:O,MATCH(A17,sheet2!A:A,0))>0,IFERROR(INDEX(LEVEL_HELPER!A:A,MATCH(INDEX(sheet2!O:O,MATCH(A17,sheet2!A:A,0)),LEVEL_HELPER!B:B,0)),H17),H17))} -> Intermediate 1 | J17: =IFERROR(MAXIFS(ATTENDANCE_LOG!F:F, ATTENDANCE_LOG!C:C, A17&"", ATTENDANCE_LOG!G:G, "Present"), "") -> 46211.583 | K17: =IF(J17="", "", TODAY() - J17) -> 1.4166667 | L17: =IF(M17="Completed (no continuation)","✅ Completed",IF(M17="Discontinued mid-course","❌ Dropped",IF(AND(ISNUMBER(K17),K17>=30),"⚠ Check",""))) | P17: =IFERROR(__xludf.DUMMYFUNCTION("IFERROR(COUNTUNIQUEIFS(ATTENDANCE_LOG!B:B,ATTENDANCE_LOG!C:C,A17),0)"),3.0) -> 3 | Q17: {=IFERROR(INDEX(ATTENDANCE_LOG!A:A,MATCH(1,(ATTENDANCE_LOG!C:C=A17)*(ATTENDANCE_LOG!F:F=MAXIFS(ATTENDANCE_LOG!F:F,ATTENDANCE_LOG!C:C,A17)),0)),"")} -> EL001 | R17: {=IFERROR(INDEX(ATTENDANCE_LOG!B:B,MATCH(1,(ATTENDANCE_LOG!C:C=A17)*(ATTENDANCE_LOG!F:F=MAXIFS(ATTENDANCE_LOG!F:F,ATTENDANCE_LOG!C:C,A17)),0)),"")} -> Business English | S17: =IFERROR(VLOOKUP(H17, LEVEL_HELPER!A:B, 2, 0), 0) -> 1 | T17: =IFERROR(VLOOKUP(I17, LEVEL_HELPER!A:B, 2, 0), 0) -> 5 | U17: =IF(S17="",0,IF(S17<=2,1,IF(S17<=4,2,IF(S17<=5.5,3,4)))) -> 1 | V17: =IF(T17="",0,IF(T17<=2,1,IF(T17<=4,2,IF(T17<=5.5,3,4)))) -> 3 | W17: =IF(OR(H17="", H17="Not Placement"), "Not tested yet", IF(V17<U17, "Regressed", IF(V17=U17, IF(T17>S17, "Minor Improvement", "No Progress"), IF(V17-U17=1, "Lv"&U17&"→Lv"&V17, "Lv"&U17&"→Lv"&V17&" (multi)")))) -> Lv1→Lv3 (multi) | Y17: 247212 | Z17: Ungroup team | AA17: Team restructuring
A18: 227155 | B18: VŨ TÚ ANH | C18: =IFERROR(__xludf.DUMMYFUNCTION("arrayformula(VLOOKUP(to_Text(A18),to_Text(sheet2!$A$1:M1005),13,0))"),"POC") -> POC | D18: =IFERROR(__xludf.DUMMYFUNCTION("arrayformula(VLOOKUP(to_Text(A18),to_Text(sheet2!$A$1:M1005),12,0))"),"QC") -> QC | E18: =IF(OR(L18="✅ Completed",L18="❌ Dropped"),"Inactive",IF(M18="Waiting for class","Waiting for class","Active")) -> Active | F18: {=IFERROR( INDEX(ATTENDANCE_INPUT!D:D, MATCH(1, (ATTENDANCE_INPUT!A:A=A18) * (ATTENDANCE_INPUT!W:W=MAXIFS(ATTENDANCE_INPUT!W:W, ATTENDANCE_INPUT!A:A, A18)), 0)), "")} -> Anh Vu | G18: {=IFERROR( INDEX(ATTENDANCE_INPUT!E:E, MATCH(1, (ATTENDANCE_INPUT!A:A=A18) * (ATTENDANCE_INPUT!W:W=MAXIFS(ATTENDANCE_INPUT!W:W, ATTENDANCE_INPUT!A:A, A18)), 0)), "")} -> Business English | H18: {=IF(ISNA(MATCH(A18,sheet2!A:A,0)),"⏳ Chưa test",IFERROR(INDEX(LEVEL_HELPER!A:A,MATCH(INDEX(sheet2!N:N,MATCH(A18,sheet2!A:A,0)),LEVEL_HELPER!B:B,0)),"⏳ Chưa test"))} -> Pre-Intermediate | I18: {=IF(ISNA(MATCH(A18,sheet2!A:A,0)),H18,IF(INDEX(sheet2!O:O,MATCH(A18,sheet2!A:A,0))>0,IFERROR(INDEX(LEVEL_HELPER!A:A,MATCH(INDEX(sheet2!O:O,MATCH(A18,sheet2!A:A,0)),LEVEL_HELPER!B:B,0)),H18),H18))} -> Pre-Intermediate 2 | J18: =IFERROR(MAXIFS(ATTENDANCE_LOG!F:F, ATTENDANCE_LOG!C:C, A18&"", ATTENDANCE_LOG!G:G, "Present"), "") -> 46211.583 | K18: =IF(J18="", "", TODAY() - J18) -> 1.4166667 | L18: =IF(M18="Completed (no continuation)","✅ Completed",IF(M18="Discontinued mid-course","❌ Dropped",IF(AND(ISNUMBER(K18),K18>=30),"⚠ Check",""))) | P18: =IFERROR(__xludf.DUMMYFUNCTION("IFERROR(COUNTUNIQUEIFS(ATTENDANCE_LOG!B:B,ATTENDANCE_LOG!C:C,A18),0)"),3.0) -> 3 | Q18: {=IFERROR(INDEX(ATTENDANCE_LOG!A:A,MATCH(1,(ATTENDANCE_LOG!C:C=A18)*(ATTENDANCE_LOG!F:F=MAXIFS(ATTENDANCE_LOG!F:F,ATTENDANCE_LOG!C:C,A18)),0)),"")} -> EL001 | R18: {=IFERROR(INDEX(ATTENDANCE_LOG!B:B,MATCH(1,(ATTENDANCE_LOG!C:C=A18)*(ATTENDANCE_LOG!F:F=MAXIFS(ATTENDANCE_LOG!F:F,ATTENDANCE_LOG!C:C,A18)),0)),"")} -> Business English | S18: =IFERROR(VLOOKUP(H18, LEVEL_HELPER!A:B, 2, 0), 0) -> 2.5 | T18: =IFERROR(VLOOKUP(I18, LEVEL_HELPER!A:B, 2, 0), 0) -> 3.5 | U18: =IF(S18="",0,IF(S18<=2,1,IF(S18<=4,2,IF(S18<=5.5,3,4)))) -> 2 | V18: =IF(T18="",0,IF(T18<=2,1,IF(T18<=4,2,IF(T18<=5.5,3,4)))) -> 2 | W18: =IF(OR(H18="", H18="Not Placement"), "Not tested yet", IF(V18<U18, "Regressed", IF(V18=U18, IF(T18>S18, "Minor Improvement", "No Progress"), IF(V18-U18=1, "Lv"&U18&"→Lv"&V18, "Lv"&U18&"→Lv"&V18&" (multi)")))) -> Minor Improvement | Y18: 247211 | Z18: Ungroup team | AA18: Team restructuring
A19: 247196 | B19: ĐOÀN TRẦN BÁ ĐẠT | C19: =IFERROR(__xludf.DUMMYFUNCTION("arrayformula(VLOOKUP(to_Text(A19),to_Text(sheet2!$A$1:M1005),13,0))"),"CHORUS") -> CHORUS | D19: =IFERROR(__xludf.DUMMYFUNCTION("arrayformula(VLOOKUP(to_Text(A19),to_Text(sheet2!$A$1:M1005),12,0))"),"DEV") -> DEV | E19: =IF(OR(L19="✅ Completed",L19="❌ Dropped"),"Inactive",IF(M19="Waiting for class","Waiting for class","Active")) -> Inactive | F19: {=IFERROR( INDEX(ATTENDANCE_INPUT!D:D, MATCH(1, (ATTENDANCE_INPUT!A:A=A19) * (ATTENDANCE_INPUT!W:W=MAXIFS(ATTENDANCE_INPUT!W:W, ATTENDANCE_INPUT!A:A, A19)), 0)), "")} -> Buu Do 1 | G19: {=IFERROR( INDEX(ATTENDANCE_INPUT!E:E, MATCH(1, (ATTENDANCE_INPUT!A:A=A19) * (ATTENDANCE_INPUT!W:W=MAXIFS(ATTENDANCE_INPUT!W:W, ATTENDANCE_INPUT!A:A, A19)), 0)), "")} -> Communication 1 | H19: {=IF(ISNA(MATCH(A19,sheet2!A:A,0)),"⏳ Chưa test",IFERROR(INDEX(LEVEL_HELPER!A:A,MATCH(INDEX(sheet2!N:N,MATCH(A19,sheet2!A:A,0)),LEVEL_HELPER!B:B,0)),"⏳ Chưa test"))} -> Beginner | I19: {=IF(ISNA(MATCH(A19,sheet2!A:A,0)),H19,IF(INDEX(sheet2!O:O,MATCH(A19,sheet2!A:A,0))>0,IFERROR(INDEX(LEVEL_HELPER!A:A,MATCH(INDEX(sheet2!O:O,MATCH(A19,sheet2!A:A,0)),LEVEL_HELPER!B:B,0)),H19),H19))} -> Intermediate | J19: =IFERROR(MAXIFS(ATTENDANCE_LOG!F:F, ATTENDANCE_LOG!C:C, A19&"", ATTENDANCE_LOG!G:G, "Present"), "") -> 45954.375 | K19: =IF(J19="", "", TODAY() - J19) -> 258.625 | L19: =IF(M19="Completed (no continuation)","✅ Completed",IF(M19="Discontinued mid-course","❌ Dropped",IF(AND(ISNUMBER(K19),K19>=30),"⚠ Check",""))) -> ✅ Completed | M19: Completed (no continuation) | N19: High workload | P19: =IFERROR(__xludf.DUMMYFUNCTION("IFERROR(COUNTUNIQUEIFS(ATTENDANCE_LOG!B:B,ATTENDANCE_LOG!C:C,A19),0)"),1.0) -> 1 | Q19: {=IFERROR(INDEX(ATTENDANCE_LOG!A:A,MATCH(1,(ATTENDANCE_LOG!C:C=A19)*(ATTENDANCE_LOG!F:F=MAXIFS(ATTENDANCE_LOG!F:F,ATTENDANCE_LOG!C:C,A19)),0)),"")} -> EL002 | R19: {=IFERROR(INDEX(ATTENDANCE_LOG!B:B,MATCH(1,(ATTENDANCE_LOG!C:C=A19)*(ATTENDANCE_LOG!F:F=MAXIFS(ATTENDANCE_LOG!F:F,ATTENDANCE_LOG!C:C,A19)),0)),"")} -> Communication 1 | S19: =IFERROR(VLOOKUP(H19, LEVEL_HELPER!A:B, 2, 0), 0) -> 1 | T19: =IFERROR(VLOOKUP(I19, LEVEL_HELPER!A:B, 2, 0), 0) -> 4.5 | U19: =IF(S19="",0,IF(S19<=2,1,IF(S19<=4,2,IF(S19<=5.5,3,4)))) -> 1 | V19: =IF(T19="",0,IF(T19<=2,1,IF(T19<=4,2,IF(T19<=5.5,3,4)))) -> 3 | W19: =IF(OR(H19="", H19="Not Placement"), "Not tested yet", IF(V19<U19, "Regressed", IF(V19=U19, IF(T19>S19, "Minor Improvement", "No Progress"), IF(V19-U19=1, "Lv"&U19&"→Lv"&V19, "Lv"&U19&"→Lv"&V19&" (multi)")))) -> Lv1→Lv3 (multi) | Y19: 247141 | Z19: Ungroup team | AA19: Team restructuring
